[2018-05-02 15:39:28,949: INFO/MainProcess] Received task: kaoweitongapp.tasks.check_neea[7c440da4-7a06-4364-bf4f-276690e31e7f]  
[2018-05-02 15:39:30,653: WARNING/ForkPoolWorker-1] balance: 70620
[2018-05-02 15:39:40,526: WARNING/ForkPoolWorker-1] 发生未知错误 请查看login_error.txt文件
[2018-05-02 15:39:40,928: WARNING/ForkPoolWorker-1] balance: 70610
[2018-05-02 15:39:49,877: WARNING/ForkPoolWorker-1] 发生未知错误 请查看login_error.txt文件
[2018-05-02 15:39:52,008: WARNING/ForkPoolWorker-1] balance: 70600
[2018-05-02 15:40:00,043: WARNING/ForkPoolWorker-1] 发生未知错误 请查看login_error.txt文件
[2018-05-02 15:40:00,456: WARNING/ForkPoolWorker-1] balance: 70590
[2018-05-02 15:40:12,002: WARNING/ForkPoolWorker-1] 2018-05-02 15:40:12login验证码错误
[2018-05-02 15:40:12,419: WARNING/ForkPoolWorker-1] balance: 70580
[2018-05-02 15:40:20,301: WARNING/ForkPoolWorker-1] 发生未知错误 请查看login_error.txt文件
[2018-05-02 15:40:23,742: WARNING/ForkPoolWorker-1] balance: 70570
[2018-05-02 15:40:40,096: WARNING/ForkPoolWorker-1] 发生未知错误 请查看login_error.txt文件
[2018-05-02 15:40:40,463: WARNING/ForkPoolWorker-1] balance: 70560
[2018-05-02 15:40:53,537: WARNING/ForkPoolWorker-1] 2018-05-02 15:40:53login验证码错误
[2018-05-02 15:40:53,948: WARNING/ForkPoolWorker-1] balance: 70550
[2018-05-02 15:40:59,632: WARNING/ForkPoolWorker-1] 发生未知错误 请查看login_error.txt文件
[2018-05-02 15:41:00,017: WARNING/ForkPoolWorker-1] balance: 70540
[2018-05-02 15:41:05,783: WARNING/ForkPoolWorker-1] 发生未知错误 请查看login_error.txt文件
[2018-05-02 15:41:07,150: WARNING/ForkPoolWorker-1] balance: 70530
[2018-05-02 15:41:17,598: WARNING/ForkPoolWorker-1] 发生未知错误 请查看login_error.txt文件
[2018-05-02 15:41:18,089: WARNING/ForkPoolWorker-1] balance: 70520
[2018-05-02 15:41:23,533: WARNING/ForkPoolWorker-1] 发生未知错误 请查看login_error.txt文件
[2018-05-02 15:41:24,386: INFO/MainProcess] Received task: kaoweitongapp.tasks.check_neea[bc84ac07-cde7-4aae-928f-4a6b772f5691]  
[2018-05-02 15:41:25,145: WARNING/ForkPoolWorker-1] 发送成功
[2018-05-02 15:41:25,182: INFO/ForkPoolWorker-1] Task kaoweitongapp.tasks.check_neea[7c440da4-7a06-4364-bf4f-276690e31e7f] succeeded in 116.23267088498687s: None
/user/local/python3/lib/python3.6/site-packages/celery/platforms.py:795: RuntimeWarning: You're running the worker with superuser privileges: this is
absolutely not recommended!

Please specify a different user using the -u option.

User information: uid=0 euid=0 gid=0 egid=0

  uid=uid, euid=euid, gid=gid, egid=egid,
[2018-05-02 15:41:25,831: WARNING/ForkPoolWorker-2] balance: 70510
[2018-05-02 15:41:36,197: WARNING/ForkPoolWorker-2] 发生未知错误 请查看login_error.txt文件
[2018-05-02 15:41:37,394: WARNING/ForkPoolWorker-2] balance: 70500
[2018-05-02 15:41:47,776: WARNING/ForkPoolWorker-2] 发生未知错误 请查看login_error.txt文件
[2018-05-02 15:41:49,019: WARNING/ForkPoolWorker-2] balance: 70490
[2018-05-02 15:41:54,752: WARNING/ForkPoolWorker-2] 发生未知错误 请查看login_error.txt文件
[2018-05-02 15:41:56,224: WARNING/ForkPoolWorker-2] balance: 70480
[2018-05-02 15:42:02,539: WARNING/ForkPoolWorker-2] 发生未知错误 请查看login_error.txt文件
[2018-05-02 15:42:05,299: WARNING/ForkPoolWorker-2] balance: 70470
[2018-05-02 15:42:14,575: WARNING/ForkPoolWorker-2] 发生未知错误 请查看login_error.txt文件
[2018-05-02 15:42:16,577: WARNING/ForkPoolWorker-2] balance: 70460
[2018-05-02 15:42:33,211: WARNING/ForkPoolWorker-2] 发生未知错误 请查看login_error.txt文件
[2018-05-02 15:42:36,837: WARNING/ForkPoolWorker-2] balance: 70450
[2018-05-02 15:42:38,749: INFO/MainProcess] Received task: kaoweitongapp.tasks.check_neea[21093813-33f2-49bc-9c6d-0ff8dcf85113]  
[2018-05-02 15:42:39,199: WARNING/ForkPoolWorker-1] balance: 70450
[2018-05-02 15:42:43,624: WARNING/ForkPoolWorker-1] 发生未知错误 请查看login_error.txt文件
[2018-05-02 15:42:44,001: WARNING/ForkPoolWorker-1] balance: 70430
[2018-05-02 15:42:44,937: WARNING/ForkPoolWorker-2] 发生未知错误 请查看login_error.txt文件
[2018-05-02 15:42:45,315: WARNING/ForkPoolWorker-2] balance: 70430
[2018-05-02 15:42:52,802: WARNING/ForkPoolWorker-2] 发生未知错误 请查看login_error.txt文件
[2018-05-02 15:42:53,265: WARNING/ForkPoolWorker-2] balance: 70420
[2018-05-02 15:42:56,343: WARNING/ForkPoolWorker-1] 发生未知错误 请查看login_error.txt文件
[2018-05-02 15:42:56,725: WARNING/ForkPoolWorker-1] balance: 70410
[2018-05-02 15:43:04,654: WARNING/ForkPoolWorker-2] 发生未知错误 请查看login_error.txt文件
[2018-05-02 15:43:05,370: WARNING/ForkPoolWorker-1] 发生未知错误 请查看login_error.txt文件
[2018-05-02 15:43:05,762: WARNING/ForkPoolWorker-2] 发送成功
[2018-05-02 15:43:05,795: WARNING/ForkPoolWorker-1] balance: 70390
[2018-05-02 15:43:05,803: INFO/ForkPoolWorker-2] Task kaoweitongapp.tasks.check_neea[bc84ac07-cde7-4aae-928f-4a6b772f5691] succeeded in 101.41632028704043s: None
[2018-05-02 15:43:12,361: WARNING/ForkPoolWorker-1] 发生未知错误 请查看login_error.txt文件
[2018-05-02 15:43:12,823: WARNING/ForkPoolWorker-1] balance: 70380
[2018-05-02 15:43:26,826: WARNING/ForkPoolWorker-1] 发生未知错误 请查看login_error.txt文件
[2018-05-02 15:43:27,246: WARNING/ForkPoolWorker-1] balance: 70370
[2018-05-02 15:43:47,046: WARNING/ForkPoolWorker-1] 2018-05-02 15:43:47login验证码错误
[2018-05-02 15:43:47,462: WARNING/ForkPoolWorker-1] balance: 70360
[2018-05-02 15:43:58,757: WARNING/ForkPoolWorker-1] 发生未知错误 请查看login_error.txt文件
[2018-05-02 15:43:59,200: WARNING/ForkPoolWorker-1] balance: 70350
[2018-05-02 15:44:06,197: WARNING/ForkPoolWorker-1] 发生未知错误 请查看login_error.txt文件
[2018-05-02 15:44:08,515: WARNING/ForkPoolWorker-1] balance: 70340
[2018-05-02 15:44:14,025: WARNING/ForkPoolWorker-1] 发生未知错误 请查看login_error.txt文件
[2018-05-02 15:44:14,326: WARNING/ForkPoolWorker-1] balance: 70330
[2018-05-02 15:44:24,298: WARNING/ForkPoolWorker-1] 发生未知错误 请查看login_error.txt文件
[2018-05-02 15:44:25,195: WARNING/ForkPoolWorker-1] 发送成功
[2018-05-02 15:44:25,236: INFO/ForkPoolWorker-1] Task kaoweitongapp.tasks.check_neea[21093813-33f2-49bc-9c6d-0ff8dcf85113] succeeded in 106.48701326799346s: None
[2018-05-03 17:33:39,621: ERROR/MainProcess] Received unregistered task of type 'kaoweitongapp.tasks.weixininfo'.
The message has been ignored and discarded.

Did you remember to import the module containing this task?
Or maybe you're using relative imports?

Please see
http://docs.celeryq.org/en/latest/internals/protocol.html
for more information.

The full contents of the message body was:
b'[["FA86A90266577732245C6B2AF3467207", "L-"], {}, {"callbacks": null, "errbacks": null, "chain": null, "chord": null}]' (117b)
Traceback (most recent call last):
  File "/user/local/python3/lib/python3.6/site-packages/celery/worker/consumer/consumer.py", line 561, in on_task_received
    strategy = strategies[type_]
KeyError: 'kaoweitongapp.tasks.weixininfo'

worker: Warm shutdown (MainProcess)
 
 -------------- celery@VM_0_13_centos v4.1.0 (latentcall)
---- **** ----- 
--- * ***  * -- Linux-3.10.0-514.26.2.el7.x86_64-x86_64-with-centos-7.2.1511-Core 2018-04-28 17:26:07
-- * - **** --- 
- ** ---------- [config]
- ** ---------- .> app:         kaoweitongapp/tasks:0x7f763dc31f28
- ** ---------- .> transport:   redis://localhost:6379/0
- ** ---------- .> results:     disabled://
- *** --- * --- .> concurrency: 2 (prefork)
-- ******* ---- .> task events: OFF (enable -E to monitor tasks in this worker)
--- ***** ----- 
 -------------- [queues]
                .> celery           exchange=celery(direct) key=celery
                

[tasks]
  . kaoweitongapp.tasks.check_neea

/user/local/python3/lib/python3.6/site-packages/celery/platforms.py:795: RuntimeWarning: You're running the worker with superuser privileges: this is
absolutely not recommended!

Please specify a different user using the -u option.

User information: uid=0 euid=0 gid=0 egid=0

  uid=uid, euid=euid, gid=gid, egid=egid,
[2018-05-03 17:38:10,158: INFO/MainProcess] Connected to redis://localhost:6379/0
[2018-05-03 17:38:10,165: INFO/MainProcess] mingle: searching for neighbors
[2018-05-03 17:38:11,180: INFO/MainProcess] mingle: all alone
[2018-05-03 17:38:11,187: INFO/MainProcess] celery@VM_0_13_centos ready.
[2018-05-03 17:38:23,139: INFO/MainProcess] Received task: kaoweitongapp.tasks.weixininfo[c5209d40-0205-47fc-b85f-cd4e7d9ed0d0]  
/user/local/python3/lib/python3.6/site-packages/celery/platforms.py:795: RuntimeWarning: You're running the worker with superuser privileges: this is
absolutely not recommended!

Please specify a different user using the -u option.

User information: uid=0 euid=0 gid=0 egid=0

  uid=uid, euid=euid, gid=gid, egid=egid,
[2018-05-03 17:38:28,147: WARNING/ForkPoolWorker-1] TD课代表.
[2018-05-03 17:38:28,147: WARNING/ForkPoolWorker-1] L-
[2018-05-03 17:38:28,147: WARNING/ForkPoolWorker-1] L-
[2018-05-03 17:38:28,148: WARNING/ForkPoolWorker-1] L-
[2018-05-03 17:38:28,148: WARNING/ForkPoolWorker-1] 渐行渐远渐无书
[2018-05-03 17:38:28,148: WARNING/ForkPoolWorker-1] L-
[2018-05-03 17:38:28,148: WARNING/ForkPoolWorker-1] damo
[2018-05-03 17:38:28,148: WARNING/ForkPoolWorker-1] L-
[2018-05-03 17:38:28,148: WARNING/ForkPoolWorker-1] TD妞
[2018-05-03 17:38:28,148: WARNING/ForkPoolWorker-1] L-
[2018-05-03 17:38:28,148: WARNING/ForkPoolWorker-1] L-
[2018-05-03 17:38:28,148: WARNING/ForkPoolWorker-1] L-
[2018-05-03 17:38:28,148: WARNING/ForkPoolWorker-1] 备尘埃
[2018-05-03 17:38:28,148: WARNING/ForkPoolWorker-1] L-
[2018-05-03 17:38:29,319: WARNING/ForkPoolWorker-1] 发送成功
[2018-05-03 17:38:29,362: INFO/ForkPoolWorker-1] Task kaoweitongapp.tasks.weixininfo[c5209d40-0205-47fc-b85f-cd4e7d9ed0d0] succeeded in 6.221276257070713s: None
[2018-05-03 17:40:22,120: INFO/MainProcess] Received task: kaoweitongapp.tasks.weixininfo[d3d50ead-b5f6-4e08-ba95-5eacbe34a7b9]  
[2018-05-03 17:40:27,126: WARNING/ForkPoolWorker-1] TD课代表.
[2018-05-03 17:40:27,126: WARNING/ForkPoolWorker-1] L-
[2018-05-03 17:40:27,126: WARNING/ForkPoolWorker-1] 渐行渐远渐无书
[2018-05-03 17:40:27,126: WARNING/ForkPoolWorker-1] L-
[2018-05-03 17:40:27,127: WARNING/ForkPoolWorker-1] TD妞
[2018-05-03 17:40:27,127: WARNING/ForkPoolWorker-1] L-
[2018-05-03 17:40:27,127: WARNING/ForkPoolWorker-1] damo
[2018-05-03 17:40:27,127: WARNING/ForkPoolWorker-1] L-
[2018-05-03 17:40:27,127: WARNING/ForkPoolWorker-1] L-
[2018-05-03 17:40:27,127: WARNING/ForkPoolWorker-1] L-
[2018-05-03 17:40:27,127: WARNING/ForkPoolWorker-1] L-
[2018-05-03 17:40:27,127: WARNING/ForkPoolWorker-1] L-
[2018-05-03 17:40:27,127: WARNING/ForkPoolWorker-1] 备尘埃
[2018-05-03 17:40:27,127: WARNING/ForkPoolWorker-1] L-
[2018-05-03 17:40:28,081: WARNING/ForkPoolWorker-1] 发送成功
[2018-05-03 17:40:28,118: INFO/ForkPoolWorker-1] Task kaoweitongapp.tasks.weixininfo[d3d50ead-b5f6-4e08-ba95-5eacbe34a7b9] succeeded in 5.997483358019963s: None

worker: Warm shutdown (MainProcess)
 
 -------------- celery@VM_0_13_centos v4.1.0 (latentcall)
---- **** ----- 
--- * ***  * -- Linux-3.10.0-514.26.2.el7.x86_64-x86_64-with-centos-7.2.1511-Core 2018-05-03 17:38:10
-- * - **** --- 
- ** ---------- [config]
- ** ---------- .> app:         kaoweitongapp/tasks:0x7fbb3ac12860
- ** ---------- .> transport:   redis://localhost:6379/0
- ** ---------- .> results:     disabled://
- *** --- * --- .> concurrency: 2 (prefork)
-- ******* ---- .> task events: OFF (enable -E to monitor tasks in this worker)
--- ***** ----- 
 -------------- [queues]
                .> celery           exchange=celery(direct) key=celery
                

[tasks]
  . kaoweitongapp.tasks.check_neea
  . kaoweitongapp.tasks.weixininfo

Traceback (most recent call last):
  File "/user/local/python3/lib/python3.6/site-packages/celery/app/utils.py", line 355, in find_app
    sym = symbol_by_name(app, imp=imp)
  File "/user/local/python3/lib/python3.6/site-packages/celery/bin/base.py", line 506, in symbol_by_name
    return imports.symbol_by_name(name, imp=imp)
  File "/user/local/python3/lib/python3.6/site-packages/kombu/utils/imports.py", line 61, in symbol_by_name
    return getattr(module, cls_name) if cls_name else module
AttributeError: module 'kaoweitongapp' has no attribute 'tasks'

During handling of the above exception, another exception occurred:

Traceback (most recent call last):
  File "/usr/bin/celery", line 11, in <module>
    sys.exit(main())
  File "/user/local/python3/lib/python3.6/site-packages/celery/__main__.py", line 14, in main
    _main()
  File "/user/local/python3/lib/python3.6/site-packages/celery/bin/celery.py", line 326, in main
    cmd.execute_from_commandline(argv)
  File "/user/local/python3/lib/python3.6/site-packages/celery/bin/celery.py", line 488, in execute_from_commandline
    super(CeleryCommand, self).execute_from_commandline(argv)))
  File "/user/local/python3/lib/python3.6/site-packages/celery/bin/base.py", line 279, in execute_from_commandline
    argv = self.setup_app_from_commandline(argv)
  File "/user/local/python3/lib/python3.6/site-packages/celery/bin/base.py", line 481, in setup_app_from_commandline
    self.app = self.find_app(app)
  File "/user/local/python3/lib/python3.6/site-packages/celery/bin/base.py", line 503, in find_app
    return find_app(app, symbol_by_name=self.symbol_by_name)
  File "/user/local/python3/lib/python3.6/site-packages/celery/app/utils.py", line 358, in find_app
    sym = imp(app)
  File "/user/local/python3/lib/python3.6/site-packages/celery/utils/imports.py", line 101, in import_from_cwd
    return imp(module, package=package)
  File "/user/local/python3/lib/python3.6/importlib/__init__.py", line 126, in import_module
    return _bootstrap._gcd_import(name[level:], package, level)
  File "<frozen importlib._bootstrap>", line 994, in _gcd_import
  File "<frozen importlib._bootstrap>", line 971, in _find_and_load
  File "<frozen importlib._bootstrap>", line 955, in _find_and_load_unlocked
  File "<frozen importlib._bootstrap>", line 665, in _load_unlocked
  File "<frozen importlib._bootstrap_external>", line 674, in exec_module
  File "<frozen importlib._bootstrap_external>", line 781, in get_code
  File "<frozen importlib._bootstrap_external>", line 741, in source_to_code
  File "<frozen importlib._bootstrap>", line 219, in _call_with_frames_removed
  File "/www/wwwroot/kaoweitong_spider/kaoweitongapp/tasks.py", line 128
    def del(self, key):
          ^
SyntaxError: invalid syntax
Traceback (most recent call last):
  File "/user/local/python3/lib/python3.6/site-packages/celery/app/utils.py", line 355, in find_app
    sym = symbol_by_name(app, imp=imp)
  File "/user/local/python3/lib/python3.6/site-packages/celery/bin/base.py", line 506, in symbol_by_name
    return imports.symbol_by_name(name, imp=imp)
  File "/user/local/python3/lib/python3.6/site-packages/kombu/utils/imports.py", line 61, in symbol_by_name
    return getattr(module, cls_name) if cls_name else module
AttributeError: module 'kaoweitongapp' has no attribute 'tasks'

During handling of the above exception, another exception occurred:

Traceback (most recent call last):
  File "/usr/bin/celery", line 11, in <module>
    sys.exit(main())
  File "/user/local/python3/lib/python3.6/site-packages/celery/__main__.py", line 14, in main
    _main()
  File "/user/local/python3/lib/python3.6/site-packages/celery/bin/celery.py", line 326, in main
    cmd.execute_from_commandline(argv)
  File "/user/local/python3/lib/python3.6/site-packages/celery/bin/celery.py", line 488, in execute_from_commandline
    super(CeleryCommand, self).execute_from_commandline(argv)))
  File "/user/local/python3/lib/python3.6/site-packages/celery/bin/base.py", line 279, in execute_from_commandline
    argv = self.setup_app_from_commandline(argv)
  File "/user/local/python3/lib/python3.6/site-packages/celery/bin/base.py", line 481, in setup_app_from_commandline
    self.app = self.find_app(app)
  File "/user/local/python3/lib/python3.6/site-packages/celery/bin/base.py", line 503, in find_app
    return find_app(app, symbol_by_name=self.symbol_by_name)
  File "/user/local/python3/lib/python3.6/site-packages/celery/app/utils.py", line 358, in find_app
    sym = imp(app)
  File "/user/local/python3/lib/python3.6/site-packages/celery/utils/imports.py", line 101, in import_from_cwd
    return imp(module, package=package)
  File "/user/local/python3/lib/python3.6/importlib/__init__.py", line 126, in import_module
    return _bootstrap._gcd_import(name[level:], package, level)
  File "<frozen importlib._bootstrap>", line 994, in _gcd_import
  File "<frozen importlib._bootstrap>", line 971, in _find_and_load
  File "<frozen importlib._bootstrap>", line 955, in _find_and_load_unlocked
  File "<frozen importlib._bootstrap>", line 665, in _load_unlocked
  File "<frozen importlib._bootstrap_external>", line 674, in exec_module
  File "<frozen importlib._bootstrap_external>", line 781, in get_code
  File "<frozen importlib._bootstrap_external>", line 741, in source_to_code
  File "<frozen importlib._bootstrap>", line 219, in _call_with_frames_removed
  File "/www/wwwroot/kaoweitong_spider/kaoweitongapp/tasks.py", line 128
    def del(self, key):
          ^
SyntaxError: invalid syntax
Traceback (most recent call last):
  File "/user/local/python3/lib/python3.6/site-packages/celery/app/utils.py", line 355, in find_app
    sym = symbol_by_name(app, imp=imp)
  File "/user/local/python3/lib/python3.6/site-packages/celery/bin/base.py", line 506, in symbol_by_name
    return imports.symbol_by_name(name, imp=imp)
  File "/user/local/python3/lib/python3.6/site-packages/kombu/utils/imports.py", line 61, in symbol_by_name
    return getattr(module, cls_name) if cls_name else module
AttributeError: module 'kaoweitongapp' has no attribute 'tasks'

During handling of the above exception, another exception occurred:

Traceback (most recent call last):
  File "/usr/bin/celery", line 11, in <module>
    sys.exit(main())
  File "/user/local/python3/lib/python3.6/site-packages/celery/__main__.py", line 14, in main
    _main()
  File "/user/local/python3/lib/python3.6/site-packages/celery/bin/celery.py", line 326, in main
    cmd.execute_from_commandline(argv)
  File "/user/local/python3/lib/python3.6/site-packages/celery/bin/celery.py", line 488, in execute_from_commandline
    super(CeleryCommand, self).execute_from_commandline(argv)))
  File "/user/local/python3/lib/python3.6/site-packages/celery/bin/base.py", line 279, in execute_from_commandline
    argv = self.setup_app_from_commandline(argv)
  File "/user/local/python3/lib/python3.6/site-packages/celery/bin/base.py", line 481, in setup_app_from_commandline
    self.app = self.find_app(app)
  File "/user/local/python3/lib/python3.6/site-packages/celery/bin/base.py", line 503, in find_app
    return find_app(app, symbol_by_name=self.symbol_by_name)
  File "/user/local/python3/lib/python3.6/site-packages/celery/app/utils.py", line 358, in find_app
    sym = imp(app)
  File "/user/local/python3/lib/python3.6/site-packages/celery/utils/imports.py", line 101, in import_from_cwd
    return imp(module, package=package)
  File "/user/local/python3/lib/python3.6/importlib/__init__.py", line 126, in import_module
    return _bootstrap._gcd_import(name[level:], package, level)
  File "<frozen importlib._bootstrap>", line 994, in _gcd_import
  File "<frozen importlib._bootstrap>", line 971, in _find_and_load
  File "<frozen importlib._bootstrap>", line 955, in _find_and_load_unlocked
  File "<frozen importlib._bootstrap>", line 665, in _load_unlocked
  File "<frozen importlib._bootstrap_external>", line 674, in exec_module
  File "<frozen importlib._bootstrap_external>", line 781, in get_code
  File "<frozen importlib._bootstrap_external>", line 741, in source_to_code
  File "<frozen importlib._bootstrap>", line 219, in _call_with_frames_removed
  File "/www/wwwroot/kaoweitong_spider/kaoweitongapp/tasks.py", line 128
    def del(self, key):
          ^
SyntaxError: invalid syntax
Traceback (most recent call last):
  File "/user/local/python3/lib/python3.6/site-packages/celery/app/utils.py", line 355, in find_app
    sym = symbol_by_name(app, imp=imp)
  File "/user/local/python3/lib/python3.6/site-packages/celery/bin/base.py", line 506, in symbol_by_name
    return imports.symbol_by_name(name, imp=imp)
  File "/user/local/python3/lib/python3.6/site-packages/kombu/utils/imports.py", line 61, in symbol_by_name
    return getattr(module, cls_name) if cls_name else module
AttributeError: module 'kaoweitongapp' has no attribute 'tasks'

During handling of the above exception, another exception occurred:

Traceback (most recent call last):
  File "/usr/bin/celery", line 11, in <module>
    sys.exit(main())
  File "/user/local/python3/lib/python3.6/site-packages/celery/__main__.py", line 14, in main
    _main()
  File "/user/local/python3/lib/python3.6/site-packages/celery/bin/celery.py", line 326, in main
    cmd.execute_from_commandline(argv)
  File "/user/local/python3/lib/python3.6/site-packages/celery/bin/celery.py", line 488, in execute_from_commandline
    super(CeleryCommand, self).execute_from_commandline(argv)))
  File "/user/local/python3/lib/python3.6/site-packages/celery/bin/base.py", line 279, in execute_from_commandline
    argv = self.setup_app_from_commandline(argv)
  File "/user/local/python3/lib/python3.6/site-packages/celery/bin/base.py", line 481, in setup_app_from_commandline
    self.app = self.find_app(app)
  File "/user/local/python3/lib/python3.6/site-packages/celery/bin/base.py", line 503, in find_app
    return find_app(app, symbol_by_name=self.symbol_by_name)
  File "/user/local/python3/lib/python3.6/site-packages/celery/app/utils.py", line 358, in find_app
    sym = imp(app)
  File "/user/local/python3/lib/python3.6/site-packages/celery/utils/imports.py", line 101, in import_from_cwd
    return imp(module, package=package)
  File "/user/local/python3/lib/python3.6/importlib/__init__.py", line 126, in import_module
    return _bootstrap._gcd_import(name[level:], package, level)
  File "<frozen importlib._bootstrap>", line 994, in _gcd_import
  File "<frozen importlib._bootstrap>", line 971, in _find_and_load
  File "<frozen importlib._bootstrap>", line 955, in _find_and_load_unlocked
  File "<frozen importlib._bootstrap>", line 665, in _load_unlocked
  File "<frozen importlib._bootstrap_external>", line 674, in exec_module
  File "<frozen importlib._bootstrap_external>", line 781, in get_code
  File "<frozen importlib._bootstrap_external>", line 741, in source_to_code
  File "<frozen importlib._bootstrap>", line 219, in _call_with_frames_removed
  File "/www/wwwroot/kaoweitong_spider/kaoweitongapp/tasks.py", line 128
    def del(self, key):
          ^
SyntaxError: invalid syntax
Traceback (most recent call last):
  File "/user/local/python3/lib/python3.6/site-packages/celery/app/utils.py", line 355, in find_app
    sym = symbol_by_name(app, imp=imp)
  File "/user/local/python3/lib/python3.6/site-packages/celery/bin/base.py", line 506, in symbol_by_name
    return imports.symbol_by_name(name, imp=imp)
  File "/user/local/python3/lib/python3.6/site-packages/kombu/utils/imports.py", line 61, in symbol_by_name
    return getattr(module, cls_name) if cls_name else module
AttributeError: module 'kaoweitongapp' has no attribute 'tasks'

During handling of the above exception, another exception occurred:

Traceback (most recent call last):
  File "/usr/bin/celery", line 11, in <module>
    sys.exit(main())
  File "/user/local/python3/lib/python3.6/site-packages/celery/__main__.py", line 14, in main
    _main()
  File "/user/local/python3/lib/python3.6/site-packages/celery/bin/celery.py", line 326, in main
    cmd.execute_from_commandline(argv)
  File "/user/local/python3/lib/python3.6/site-packages/celery/bin/celery.py", line 488, in execute_from_commandline
    super(CeleryCommand, self).execute_from_commandline(argv)))
  File "/user/local/python3/lib/python3.6/site-packages/celery/bin/base.py", line 279, in execute_from_commandline
    argv = self.setup_app_from_commandline(argv)
  File "/user/local/python3/lib/python3.6/site-packages/celery/bin/base.py", line 481, in setup_app_from_commandline
    self.app = self.find_app(app)
  File "/user/local/python3/lib/python3.6/site-packages/celery/bin/base.py", line 503, in find_app
    return find_app(app, symbol_by_name=self.symbol_by_name)
  File "/user/local/python3/lib/python3.6/site-packages/celery/app/utils.py", line 358, in find_app
    sym = imp(app)
  File "/user/local/python3/lib/python3.6/site-packages/celery/utils/imports.py", line 101, in import_from_cwd
    return imp(module, package=package)
  File "/user/local/python3/lib/python3.6/importlib/__init__.py", line 126, in import_module
    return _bootstrap._gcd_import(name[level:], package, level)
  File "<frozen importlib._bootstrap>", line 994, in _gcd_import
  File "<frozen importlib._bootstrap>", line 971, in _find_and_load
  File "<frozen importlib._bootstrap>", line 955, in _find_and_load_unlocked
  File "<frozen importlib._bootstrap>", line 665, in _load_unlocked
  File "<frozen importlib._bootstrap_external>", line 674, in exec_module
  File "<frozen importlib._bootstrap_external>", line 781, in get_code
  File "<frozen importlib._bootstrap_external>", line 741, in source_to_code
  File "<frozen importlib._bootstrap>", line 219, in _call_with_frames_removed
  File "/www/wwwroot/kaoweitong_spider/kaoweitongapp/tasks.py", line 128
    def del(self, key):
          ^
SyntaxError: invalid syntax
Traceback (most recent call last):
  File "/user/local/python3/lib/python3.6/site-packages/celery/app/utils.py", line 355, in find_app
    sym = symbol_by_name(app, imp=imp)
  File "/user/local/python3/lib/python3.6/site-packages/celery/bin/base.py", line 506, in symbol_by_name
    return imports.symbol_by_name(name, imp=imp)
  File "/user/local/python3/lib/python3.6/site-packages/kombu/utils/imports.py", line 61, in symbol_by_name
    return getattr(module, cls_name) if cls_name else module
AttributeError: module 'kaoweitongapp' has no attribute 'tasks'

During handling of the above exception, another exception occurred:

Traceback (most recent call last):
  File "/usr/bin/celery", line 11, in <module>
    sys.exit(main())
  File "/user/local/python3/lib/python3.6/site-packages/celery/__main__.py", line 14, in main
    _main()
  File "/user/local/python3/lib/python3.6/site-packages/celery/bin/celery.py", line 326, in main
    cmd.execute_from_commandline(argv)
  File "/user/local/python3/lib/python3.6/site-packages/celery/bin/celery.py", line 488, in execute_from_commandline
    super(CeleryCommand, self).execute_from_commandline(argv)))
  File "/user/local/python3/lib/python3.6/site-packages/celery/bin/base.py", line 279, in execute_from_commandline
    argv = self.setup_app_from_commandline(argv)
  File "/user/local/python3/lib/python3.6/site-packages/celery/bin/base.py", line 481, in setup_app_from_commandline
    self.app = self.find_app(app)
  File "/user/local/python3/lib/python3.6/site-packages/celery/bin/base.py", line 503, in find_app
    return find_app(app, symbol_by_name=self.symbol_by_name)
  File "/user/local/python3/lib/python3.6/site-packages/celery/app/utils.py", line 358, in find_app
    sym = imp(app)
  File "/user/local/python3/lib/python3.6/site-packages/celery/utils/imports.py", line 101, in import_from_cwd
    return imp(module, package=package)
  File "/user/local/python3/lib/python3.6/importlib/__init__.py", line 126, in import_module
    return _bootstrap._gcd_import(name[level:], package, level)
  File "<frozen importlib._bootstrap>", line 994, in _gcd_import
  File "<frozen importlib._bootstrap>", line 971, in _find_and_load
  File "<frozen importlib._bootstrap>", line 955, in _find_and_load_unlocked
  File "<frozen importlib._bootstrap>", line 665, in _load_unlocked
  File "<frozen importlib._bootstrap_external>", line 674, in exec_module
  File "<frozen importlib._bootstrap_external>", line 781, in get_code
  File "<frozen importlib._bootstrap_external>", line 741, in source_to_code
  File "<frozen importlib._bootstrap>", line 219, in _call_with_frames_removed
  File "/www/wwwroot/kaoweitong_spider/kaoweitongapp/tasks.py", line 128
    def del(self, key):
          ^
SyntaxError: invalid syntax
Traceback (most recent call last):
  File "/user/local/python3/lib/python3.6/site-packages/celery/app/utils.py", line 355, in find_app
    sym = symbol_by_name(app, imp=imp)
  File "/user/local/python3/lib/python3.6/site-packages/celery/bin/base.py", line 506, in symbol_by_name
    return imports.symbol_by_name(name, imp=imp)
  File "/user/local/python3/lib/python3.6/site-packages/kombu/utils/imports.py", line 61, in symbol_by_name
    return getattr(module, cls_name) if cls_name else module
AttributeError: module 'kaoweitongapp' has no attribute 'tasks'

During handling of the above exception, another exception occurred:

Traceback (most recent call last):
  File "/usr/bin/celery", line 11, in <module>
    sys.exit(main())
  File "/user/local/python3/lib/python3.6/site-packages/celery/__main__.py", line 14, in main
    _main()
  File "/user/local/python3/lib/python3.6/site-packages/celery/bin/celery.py", line 326, in main
    cmd.execute_from_commandline(argv)
  File "/user/local/python3/lib/python3.6/site-packages/celery/bin/celery.py", line 488, in execute_from_commandline
    super(CeleryCommand, self).execute_from_commandline(argv)))
  File "/user/local/python3/lib/python3.6/site-packages/celery/bin/base.py", line 279, in execute_from_commandline
    argv = self.setup_app_from_commandline(argv)
  File "/user/local/python3/lib/python3.6/site-packages/celery/bin/base.py", line 481, in setup_app_from_commandline
    self.app = self.find_app(app)
  File "/user/local/python3/lib/python3.6/site-packages/celery/bin/base.py", line 503, in find_app
    return find_app(app, symbol_by_name=self.symbol_by_name)
  File "/user/local/python3/lib/python3.6/site-packages/celery/app/utils.py", line 358, in find_app
    sym = imp(app)
  File "/user/local/python3/lib/python3.6/site-packages/celery/utils/imports.py", line 101, in import_from_cwd
    return imp(module, package=package)
  File "/user/local/python3/lib/python3.6/importlib/__init__.py", line 126, in import_module
    return _bootstrap._gcd_import(name[level:], package, level)
  File "<frozen importlib._bootstrap>", line 994, in _gcd_import
  File "<frozen importlib._bootstrap>", line 971, in _find_and_load
  File "<frozen importlib._bootstrap>", line 955, in _find_and_load_unlocked
  File "<frozen importlib._bootstrap>", line 665, in _load_unlocked
  File "<frozen importlib._bootstrap_external>", line 674, in exec_module
  File "<frozen importlib._bootstrap_external>", line 781, in get_code
  File "<frozen importlib._bootstrap_external>", line 741, in source_to_code
  File "<frozen importlib._bootstrap>", line 219, in _call_with_frames_removed
  File "/www/wwwroot/kaoweitong_spider/kaoweitongapp/tasks.py", line 128
    def del(self, key):
          ^
SyntaxError: invalid syntax
Traceback (most recent call last):
  File "/user/local/python3/lib/python3.6/site-packages/celery/app/utils.py", line 355, in find_app
    sym = symbol_by_name(app, imp=imp)
  File "/user/local/python3/lib/python3.6/site-packages/celery/bin/base.py", line 506, in symbol_by_name
    return imports.symbol_by_name(name, imp=imp)
  File "/user/local/python3/lib/python3.6/site-packages/kombu/utils/imports.py", line 61, in symbol_by_name
    return getattr(module, cls_name) if cls_name else module
AttributeError: module 'kaoweitongapp' has no attribute 'tasks'

During handling of the above exception, another exception occurred:

Traceback (most recent call last):
  File "/usr/bin/celery", line 11, in <module>
    sys.exit(main())
  File "/user/local/python3/lib/python3.6/site-packages/celery/__main__.py", line 14, in main
    _main()
  File "/user/local/python3/lib/python3.6/site-packages/celery/bin/celery.py", line 326, in main
    cmd.execute_from_commandline(argv)
  File "/user/local/python3/lib/python3.6/site-packages/celery/bin/celery.py", line 488, in execute_from_commandline
    super(CeleryCommand, self).execute_from_commandline(argv)))
  File "/user/local/python3/lib/python3.6/site-packages/celery/bin/base.py", line 279, in execute_from_commandline
    argv = self.setup_app_from_commandline(argv)
  File "/user/local/python3/lib/python3.6/site-packages/celery/bin/base.py", line 481, in setup_app_from_commandline
    self.app = self.find_app(app)
  File "/user/local/python3/lib/python3.6/site-packages/celery/bin/base.py", line 503, in find_app
    return find_app(app, symbol_by_name=self.symbol_by_name)
  File "/user/local/python3/lib/python3.6/site-packages/celery/app/utils.py", line 358, in find_app
    sym = imp(app)
  File "/user/local/python3/lib/python3.6/site-packages/celery/utils/imports.py", line 101, in import_from_cwd
    return imp(module, package=package)
  File "/user/local/python3/lib/python3.6/importlib/__init__.py", line 126, in import_module
    return _bootstrap._gcd_import(name[level:], package, level)
  File "<frozen importlib._bootstrap>", line 994, in _gcd_import
  File "<frozen importlib._bootstrap>", line 971, in _find_and_load
  File "<frozen importlib._bootstrap>", line 955, in _find_and_load_unlocked
  File "<frozen importlib._bootstrap>", line 665, in _load_unlocked
  File "<frozen importlib._bootstrap_external>", line 674, in exec_module
  File "<frozen importlib._bootstrap_external>", line 781, in get_code
  File "<frozen importlib._bootstrap_external>", line 741, in source_to_code
  File "<frozen importlib._bootstrap>", line 219, in _call_with_frames_removed
  File "/www/wwwroot/kaoweitong_spider/kaoweitongapp/tasks.py", line 128
    def del(self, key):
          ^
SyntaxError: invalid syntax
Traceback (most recent call last):
  File "/user/local/python3/lib/python3.6/site-packages/celery/app/utils.py", line 355, in find_app
    sym = symbol_by_name(app, imp=imp)
  File "/user/local/python3/lib/python3.6/site-packages/celery/bin/base.py", line 506, in symbol_by_name
    return imports.symbol_by_name(name, imp=imp)
  File "/user/local/python3/lib/python3.6/site-packages/kombu/utils/imports.py", line 61, in symbol_by_name
    return getattr(module, cls_name) if cls_name else module
AttributeError: module 'kaoweitongapp' has no attribute 'tasks'

During handling of the above exception, another exception occurred:

Traceback (most recent call last):
  File "/usr/bin/celery", line 11, in <module>
    sys.exit(main())
  File "/user/local/python3/lib/python3.6/site-packages/celery/__main__.py", line 14, in main
    _main()
  File "/user/local/python3/lib/python3.6/site-packages/celery/bin/celery.py", line 326, in main
    cmd.execute_from_commandline(argv)
  File "/user/local/python3/lib/python3.6/site-packages/celery/bin/celery.py", line 488, in execute_from_commandline
    super(CeleryCommand, self).execute_from_commandline(argv)))
  File "/user/local/python3/lib/python3.6/site-packages/celery/bin/base.py", line 279, in execute_from_commandline
    argv = self.setup_app_from_commandline(argv)
  File "/user/local/python3/lib/python3.6/site-packages/celery/bin/base.py", line 481, in setup_app_from_commandline
    self.app = self.find_app(app)
  File "/user/local/python3/lib/python3.6/site-packages/celery/bin/base.py", line 503, in find_app
    return find_app(app, symbol_by_name=self.symbol_by_name)
  File "/user/local/python3/lib/python3.6/site-packages/celery/app/utils.py", line 358, in find_app
    sym = imp(app)
  File "/user/local/python3/lib/python3.6/site-packages/celery/utils/imports.py", line 101, in import_from_cwd
    return imp(module, package=package)
  File "/user/local/python3/lib/python3.6/importlib/__init__.py", line 126, in import_module
    return _bootstrap._gcd_import(name[level:], package, level)
  File "<frozen importlib._bootstrap>", line 994, in _gcd_import
  File "<frozen importlib._bootstrap>", line 971, in _find_and_load
  File "<frozen importlib._bootstrap>", line 955, in _find_and_load_unlocked
  File "<frozen importlib._bootstrap>", line 665, in _load_unlocked
  File "<frozen importlib._bootstrap_external>", line 674, in exec_module
  File "<frozen importlib._bootstrap_external>", line 781, in get_code
  File "<frozen importlib._bootstrap_external>", line 741, in source_to_code
  File "<frozen importlib._bootstrap>", line 219, in _call_with_frames_removed
  File "/www/wwwroot/kaoweitong_spider/kaoweitongapp/tasks.py", line 128
    def del(self, key):
          ^
SyntaxError: invalid syntax
Traceback (most recent call last):
  File "/user/local/python3/lib/python3.6/site-packages/celery/app/utils.py", line 355, in find_app
    sym = symbol_by_name(app, imp=imp)
  File "/user/local/python3/lib/python3.6/site-packages/celery/bin/base.py", line 506, in symbol_by_name
    return imports.symbol_by_name(name, imp=imp)
  File "/user/local/python3/lib/python3.6/site-packages/kombu/utils/imports.py", line 61, in symbol_by_name
    return getattr(module, cls_name) if cls_name else module
AttributeError: module 'kaoweitongapp' has no attribute 'tasks'

During handling of the above exception, another exception occurred:

Traceback (most recent call last):
  File "/usr/bin/celery", line 11, in <module>
    sys.exit(main())
  File "/user/local/python3/lib/python3.6/site-packages/celery/__main__.py", line 14, in main
    _main()
  File "/user/local/python3/lib/python3.6/site-packages/celery/bin/celery.py", line 326, in main
    cmd.execute_from_commandline(argv)
  File "/user/local/python3/lib/python3.6/site-packages/celery/bin/celery.py", line 488, in execute_from_commandline
    super(CeleryCommand, self).execute_from_commandline(argv)))
  File "/user/local/python3/lib/python3.6/site-packages/celery/bin/base.py", line 279, in execute_from_commandline
    argv = self.setup_app_from_commandline(argv)
  File "/user/local/python3/lib/python3.6/site-packages/celery/bin/base.py", line 481, in setup_app_from_commandline
    self.app = self.find_app(app)
  File "/user/local/python3/lib/python3.6/site-packages/celery/bin/base.py", line 503, in find_app
    return find_app(app, symbol_by_name=self.symbol_by_name)
  File "/user/local/python3/lib/python3.6/site-packages/celery/app/utils.py", line 358, in find_app
    sym = imp(app)
  File "/user/local/python3/lib/python3.6/site-packages/celery/utils/imports.py", line 101, in import_from_cwd
    return imp(module, package=package)
  File "/user/local/python3/lib/python3.6/importlib/__init__.py", line 126, in import_module
    return _bootstrap._gcd_import(name[level:], package, level)
  File "<frozen importlib._bootstrap>", line 994, in _gcd_import
  File "<frozen importlib._bootstrap>", line 971, in _find_and_load
  File "<frozen importlib._bootstrap>", line 955, in _find_and_load_unlocked
  File "<frozen importlib._bootstrap>", line 665, in _load_unlocked
  File "<frozen importlib._bootstrap_external>", line 674, in exec_module
  File "<frozen importlib._bootstrap_external>", line 781, in get_code
  File "<frozen importlib._bootstrap_external>", line 741, in source_to_code
  File "<frozen importlib._bootstrap>", line 219, in _call_with_frames_removed
  File "/www/wwwroot/kaoweitong_spider/kaoweitongapp/tasks.py", line 128
    def del(self, key):
          ^
SyntaxError: invalid syntax
Traceback (most recent call last):
  File "/user/local/python3/lib/python3.6/site-packages/celery/app/utils.py", line 355, in find_app
    sym = symbol_by_name(app, imp=imp)
  File "/user/local/python3/lib/python3.6/site-packages/celery/bin/base.py", line 506, in symbol_by_name
    return imports.symbol_by_name(name, imp=imp)
  File "/user/local/python3/lib/python3.6/site-packages/kombu/utils/imports.py", line 61, in symbol_by_name
    return getattr(module, cls_name) if cls_name else module
AttributeError: module 'kaoweitongapp' has no attribute 'tasks'

During handling of the above exception, another exception occurred:

Traceback (most recent call last):
  File "/usr/bin/celery", line 11, in <module>
    sys.exit(main())
  File "/user/local/python3/lib/python3.6/site-packages/celery/__main__.py", line 14, in main
    _main()
  File "/user/local/python3/lib/python3.6/site-packages/celery/bin/celery.py", line 326, in main
    cmd.execute_from_commandline(argv)
  File "/user/local/python3/lib/python3.6/site-packages/celery/bin/celery.py", line 488, in execute_from_commandline
    super(CeleryCommand, self).execute_from_commandline(argv)))
  File "/user/local/python3/lib/python3.6/site-packages/celery/bin/base.py", line 279, in execute_from_commandline
    argv = self.setup_app_from_commandline(argv)
  File "/user/local/python3/lib/python3.6/site-packages/celery/bin/base.py", line 481, in setup_app_from_commandline
    self.app = self.find_app(app)
  File "/user/local/python3/lib/python3.6/site-packages/celery/bin/base.py", line 503, in find_app
    return find_app(app, symbol_by_name=self.symbol_by_name)
  File "/user/local/python3/lib/python3.6/site-packages/celery/app/utils.py", line 358, in find_app
    sym = imp(app)
  File "/user/local/python3/lib/python3.6/site-packages/celery/utils/imports.py", line 101, in import_from_cwd
    return imp(module, package=package)
  File "/user/local/python3/lib/python3.6/importlib/__init__.py", line 126, in import_module
    return _bootstrap._gcd_import(name[level:], package, level)
  File "<frozen importlib._bootstrap>", line 994, in _gcd_import
  File "<frozen importlib._bootstrap>", line 971, in _find_and_load
  File "<frozen importlib._bootstrap>", line 955, in _find_and_load_unlocked
  File "<frozen importlib._bootstrap>", line 665, in _load_unlocked
  File "<frozen importlib._bootstrap_external>", line 674, in exec_module
  File "<frozen importlib._bootstrap_external>", line 781, in get_code
  File "<frozen importlib._bootstrap_external>", line 741, in source_to_code
  File "<frozen importlib._bootstrap>", line 219, in _call_with_frames_removed
  File "/www/wwwroot/kaoweitong_spider/kaoweitongapp/tasks.py", line 128
    def del(self, key):
          ^
SyntaxError: invalid syntax
Traceback (most recent call last):
  File "/user/local/python3/lib/python3.6/site-packages/celery/app/utils.py", line 355, in find_app
    sym = symbol_by_name(app, imp=imp)
  File "/user/local/python3/lib/python3.6/site-packages/celery/bin/base.py", line 506, in symbol_by_name
    return imports.symbol_by_name(name, imp=imp)
  File "/user/local/python3/lib/python3.6/site-packages/kombu/utils/imports.py", line 61, in symbol_by_name
    return getattr(module, cls_name) if cls_name else module
AttributeError: module 'kaoweitongapp' has no attribute 'tasks'

During handling of the above exception, another exception occurred:

Traceback (most recent call last):
  File "/usr/bin/celery", line 11, in <module>
    sys.exit(main())
  File "/user/local/python3/lib/python3.6/site-packages/celery/__main__.py", line 14, in main
    _main()
  File "/user/local/python3/lib/python3.6/site-packages/celery/bin/celery.py", line 326, in main
    cmd.execute_from_commandline(argv)
  File "/user/local/python3/lib/python3.6/site-packages/celery/bin/celery.py", line 488, in execute_from_commandline
    super(CeleryCommand, self).execute_from_commandline(argv)))
  File "/user/local/python3/lib/python3.6/site-packages/celery/bin/base.py", line 279, in execute_from_commandline
    argv = self.setup_app_from_commandline(argv)
  File "/user/local/python3/lib/python3.6/site-packages/celery/bin/base.py", line 481, in setup_app_from_commandline
    self.app = self.find_app(app)
  File "/user/local/python3/lib/python3.6/site-packages/celery/bin/base.py", line 503, in find_app
    return find_app(app, symbol_by_name=self.symbol_by_name)
  File "/user/local/python3/lib/python3.6/site-packages/celery/app/utils.py", line 358, in find_app
    sym = imp(app)
  File "/user/local/python3/lib/python3.6/site-packages/celery/utils/imports.py", line 101, in import_from_cwd
    return imp(module, package=package)
  File "/user/local/python3/lib/python3.6/importlib/__init__.py", line 126, in import_module
    return _bootstrap._gcd_import(name[level:], package, level)
  File "<frozen importlib._bootstrap>", line 994, in _gcd_import
  File "<frozen importlib._bootstrap>", line 971, in _find_and_load
  File "<frozen importlib._bootstrap>", line 955, in _find_and_load_unlocked
  File "<frozen importlib._bootstrap>", line 665, in _load_unlocked
  File "<frozen importlib._bootstrap_external>", line 674, in exec_module
  File "<frozen importlib._bootstrap_external>", line 781, in get_code
  File "<frozen importlib._bootstrap_external>", line 741, in source_to_code
  File "<frozen importlib._bootstrap>", line 219, in _call_with_frames_removed
  File "/www/wwwroot/kaoweitong_spider/kaoweitongapp/tasks.py", line 128
    def del(self, key):
          ^
SyntaxError: invalid syntax
Traceback (most recent call last):
  File "/user/local/python3/lib/python3.6/site-packages/celery/app/utils.py", line 355, in find_app
    sym = symbol_by_name(app, imp=imp)
  File "/user/local/python3/lib/python3.6/site-packages/celery/bin/base.py", line 506, in symbol_by_name
    return imports.symbol_by_name(name, imp=imp)
  File "/user/local/python3/lib/python3.6/site-packages/kombu/utils/imports.py", line 61, in symbol_by_name
    return getattr(module, cls_name) if cls_name else module
AttributeError: module 'kaoweitongapp' has no attribute 'tasks'

During handling of the above exception, another exception occurred:

Traceback (most recent call last):
  File "/usr/bin/celery", line 11, in <module>
    sys.exit(main())
  File "/user/local/python3/lib/python3.6/site-packages/celery/__main__.py", line 14, in main
    _main()
  File "/user/local/python3/lib/python3.6/site-packages/celery/bin/celery.py", line 326, in main
    cmd.execute_from_commandline(argv)
  File "/user/local/python3/lib/python3.6/site-packages/celery/bin/celery.py", line 488, in execute_from_commandline
    super(CeleryCommand, self).execute_from_commandline(argv)))
  File "/user/local/python3/lib/python3.6/site-packages/celery/bin/base.py", line 279, in execute_from_commandline
    argv = self.setup_app_from_commandline(argv)
  File "/user/local/python3/lib/python3.6/site-packages/celery/bin/base.py", line 481, in setup_app_from_commandline
    self.app = self.find_app(app)
  File "/user/local/python3/lib/python3.6/site-packages/celery/bin/base.py", line 503, in find_app
    return find_app(app, symbol_by_name=self.symbol_by_name)
  File "/user/local/python3/lib/python3.6/site-packages/celery/app/utils.py", line 358, in find_app
    sym = imp(app)
  File "/user/local/python3/lib/python3.6/site-packages/celery/utils/imports.py", line 101, in import_from_cwd
    return imp(module, package=package)
  File "/user/local/python3/lib/python3.6/importlib/__init__.py", line 126, in import_module
    return _bootstrap._gcd_import(name[level:], package, level)
  File "<frozen importlib._bootstrap>", line 994, in _gcd_import
  File "<frozen importlib._bootstrap>", line 971, in _find_and_load
  File "<frozen importlib._bootstrap>", line 955, in _find_and_load_unlocked
  File "<frozen importlib._bootstrap>", line 665, in _load_unlocked
  File "<frozen importlib._bootstrap_external>", line 674, in exec_module
  File "<frozen importlib._bootstrap_external>", line 781, in get_code
  File "<frozen importlib._bootstrap_external>", line 741, in source_to_code
  File "<frozen importlib._bootstrap>", line 219, in _call_with_frames_removed
  File "/www/wwwroot/kaoweitong_spider/kaoweitongapp/tasks.py", line 128
    def del(self, key):
          ^
SyntaxError: invalid syntax
Traceback (most recent call last):
  File "/user/local/python3/lib/python3.6/site-packages/celery/app/utils.py", line 355, in find_app
    sym = symbol_by_name(app, imp=imp)
  File "/user/local/python3/lib/python3.6/site-packages/celery/bin/base.py", line 506, in symbol_by_name
    return imports.symbol_by_name(name, imp=imp)
  File "/user/local/python3/lib/python3.6/site-packages/kombu/utils/imports.py", line 61, in symbol_by_name
    return getattr(module, cls_name) if cls_name else module
AttributeError: module 'kaoweitongapp' has no attribute 'tasks'

During handling of the above exception, another exception occurred:

Traceback (most recent call last):
  File "/usr/bin/celery", line 11, in <module>
    sys.exit(main())
  File "/user/local/python3/lib/python3.6/site-packages/celery/__main__.py", line 14, in main
    _main()
  File "/user/local/python3/lib/python3.6/site-packages/celery/bin/celery.py", line 326, in main
    cmd.execute_from_commandline(argv)
  File "/user/local/python3/lib/python3.6/site-packages/celery/bin/celery.py", line 488, in execute_from_commandline
    super(CeleryCommand, self).execute_from_commandline(argv)))
  File "/user/local/python3/lib/python3.6/site-packages/celery/bin/base.py", line 279, in execute_from_commandline
    argv = self.setup_app_from_commandline(argv)
  File "/user/local/python3/lib/python3.6/site-packages/celery/bin/base.py", line 481, in setup_app_from_commandline
    self.app = self.find_app(app)
  File "/user/local/python3/lib/python3.6/site-packages/celery/bin/base.py", line 503, in find_app
    return find_app(app, symbol_by_name=self.symbol_by_name)
  File "/user/local/python3/lib/python3.6/site-packages/celery/app/utils.py", line 358, in find_app
    sym = imp(app)
  File "/user/local/python3/lib/python3.6/site-packages/celery/utils/imports.py", line 101, in import_from_cwd
    return imp(module, package=package)
  File "/user/local/python3/lib/python3.6/importlib/__init__.py", line 126, in import_module
    return _bootstrap._gcd_import(name[level:], package, level)
  File "<frozen importlib._bootstrap>", line 994, in _gcd_import
  File "<frozen importlib._bootstrap>", line 971, in _find_and_load
  File "<frozen importlib._bootstrap>", line 955, in _find_and_load_unlocked
  File "<frozen importlib._bootstrap>", line 665, in _load_unlocked
  File "<frozen importlib._bootstrap_external>", line 674, in exec_module
  File "<frozen importlib._bootstrap_external>", line 781, in get_code
  File "<frozen importlib._bootstrap_external>", line 741, in source_to_code
  File "<frozen importlib._bootstrap>", line 219, in _call_with_frames_removed
  File "/www/wwwroot/kaoweitong_spider/kaoweitongapp/tasks.py", line 128
    def del(self, key):
          ^
SyntaxError: invalid syntax
Traceback (most recent call last):
  File "/user/local/python3/lib/python3.6/site-packages/celery/app/utils.py", line 355, in find_app
    sym = symbol_by_name(app, imp=imp)
  File "/user/local/python3/lib/python3.6/site-packages/celery/bin/base.py", line 506, in symbol_by_name
    return imports.symbol_by_name(name, imp=imp)
  File "/user/local/python3/lib/python3.6/site-packages/kombu/utils/imports.py", line 61, in symbol_by_name
    return getattr(module, cls_name) if cls_name else module
AttributeError: module 'kaoweitongapp' has no attribute 'tasks'

During handling of the above exception, another exception occurred:

Traceback (most recent call last):
  File "/usr/bin/celery", line 11, in <module>
    sys.exit(main())
  File "/user/local/python3/lib/python3.6/site-packages/celery/__main__.py", line 14, in main
    _main()
  File "/user/local/python3/lib/python3.6/site-packages/celery/bin/celery.py", line 326, in main
    cmd.execute_from_commandline(argv)
  File "/user/local/python3/lib/python3.6/site-packages/celery/bin/celery.py", line 488, in execute_from_commandline
    super(CeleryCommand, self).execute_from_commandline(argv)))
  File "/user/local/python3/lib/python3.6/site-packages/celery/bin/base.py", line 279, in execute_from_commandline
    argv = self.setup_app_from_commandline(argv)
  File "/user/local/python3/lib/python3.6/site-packages/celery/bin/base.py", line 481, in setup_app_from_commandline
    self.app = self.find_app(app)
  File "/user/local/python3/lib/python3.6/site-packages/celery/bin/base.py", line 503, in find_app
    return find_app(app, symbol_by_name=self.symbol_by_name)
  File "/user/local/python3/lib/python3.6/site-packages/celery/app/utils.py", line 358, in find_app
    sym = imp(app)
  File "/user/local/python3/lib/python3.6/site-packages/celery/utils/imports.py", line 101, in import_from_cwd
    return imp(module, package=package)
  File "/user/local/python3/lib/python3.6/importlib/__init__.py", line 126, in import_module
    return _bootstrap._gcd_import(name[level:], package, level)
  File "<frozen importlib._bootstrap>", line 994, in _gcd_import
  File "<frozen importlib._bootstrap>", line 971, in _find_and_load
  File "<frozen importlib._bootstrap>", line 955, in _find_and_load_unlocked
  File "<frozen importlib._bootstrap>", line 665, in _load_unlocked
  File "<frozen importlib._bootstrap_external>", line 674, in exec_module
  File "<frozen importlib._bootstrap_external>", line 781, in get_code
  File "<frozen importlib._bootstrap_external>", line 741, in source_to_code
  File "<frozen importlib._bootstrap>", line 219, in _call_with_frames_removed
  File "/www/wwwroot/kaoweitong_spider/kaoweitongapp/tasks.py", line 128
    def del(self, key):
          ^
SyntaxError: invalid syntax
Traceback (most recent call last):
  File "/user/local/python3/lib/python3.6/site-packages/celery/app/utils.py", line 355, in find_app
    sym = symbol_by_name(app, imp=imp)
  File "/user/local/python3/lib/python3.6/site-packages/celery/bin/base.py", line 506, in symbol_by_name
    return imports.symbol_by_name(name, imp=imp)
  File "/user/local/python3/lib/python3.6/site-packages/kombu/utils/imports.py", line 61, in symbol_by_name
    return getattr(module, cls_name) if cls_name else module
AttributeError: module 'kaoweitongapp' has no attribute 'tasks'

During handling of the above exception, another exception occurred:

Traceback (most recent call last):
  File "/usr/bin/celery", line 11, in <module>
    sys.exit(main())
  File "/user/local/python3/lib/python3.6/site-packages/celery/__main__.py", line 14, in main
    _main()
  File "/user/local/python3/lib/python3.6/site-packages/celery/bin/celery.py", line 326, in main
    cmd.execute_from_commandline(argv)
  File "/user/local/python3/lib/python3.6/site-packages/celery/bin/celery.py", line 488, in execute_from_commandline
    super(CeleryCommand, self).execute_from_commandline(argv)))
  File "/user/local/python3/lib/python3.6/site-packages/celery/bin/base.py", line 279, in execute_from_commandline
    argv = self.setup_app_from_commandline(argv)
  File "/user/local/python3/lib/python3.6/site-packages/celery/bin/base.py", line 481, in setup_app_from_commandline
    self.app = self.find_app(app)
  File "/user/local/python3/lib/python3.6/site-packages/celery/bin/base.py", line 503, in find_app
    return find_app(app, symbol_by_name=self.symbol_by_name)
  File "/user/local/python3/lib/python3.6/site-packages/celery/app/utils.py", line 358, in find_app
    sym = imp(app)
  File "/user/local/python3/lib/python3.6/site-packages/celery/utils/imports.py", line 101, in import_from_cwd
    return imp(module, package=package)
  File "/user/local/python3/lib/python3.6/importlib/__init__.py", line 126, in import_module
    return _bootstrap._gcd_import(name[level:], package, level)
  File "<frozen importlib._bootstrap>", line 994, in _gcd_import
  File "<frozen importlib._bootstrap>", line 971, in _find_and_load
  File "<frozen importlib._bootstrap>", line 955, in _find_and_load_unlocked
  File "<frozen importlib._bootstrap>", line 665, in _load_unlocked
  File "<frozen importlib._bootstrap_external>", line 674, in exec_module
  File "<frozen importlib._bootstrap_external>", line 781, in get_code
  File "<frozen importlib._bootstrap_external>", line 741, in source_to_code
  File "<frozen importlib._bootstrap>", line 219, in _call_with_frames_removed
  File "/www/wwwroot/kaoweitong_spider/kaoweitongapp/tasks.py", line 130
    self.sr.del(key)
              ^
SyntaxError: invalid syntax
Traceback (most recent call last):
  File "/user/local/python3/lib/python3.6/site-packages/celery/app/utils.py", line 355, in find_app
    sym = symbol_by_name(app, imp=imp)
  File "/user/local/python3/lib/python3.6/site-packages/celery/bin/base.py", line 506, in symbol_by_name
    return imports.symbol_by_name(name, imp=imp)
  File "/user/local/python3/lib/python3.6/site-packages/kombu/utils/imports.py", line 61, in symbol_by_name
    return getattr(module, cls_name) if cls_name else module
AttributeError: module 'kaoweitongapp' has no attribute 'tasks'

During handling of the above exception, another exception occurred:

Traceback (most recent call last):
  File "/usr/bin/celery", line 11, in <module>
    sys.exit(main())
  File "/user/local/python3/lib/python3.6/site-packages/celery/__main__.py", line 14, in main
    _main()
  File "/user/local/python3/lib/python3.6/site-packages/celery/bin/celery.py", line 326, in main
    cmd.execute_from_commandline(argv)
  File "/user/local/python3/lib/python3.6/site-packages/celery/bin/celery.py", line 488, in execute_from_commandline
    super(CeleryCommand, self).execute_from_commandline(argv)))
  File "/user/local/python3/lib/python3.6/site-packages/celery/bin/base.py", line 279, in execute_from_commandline
    argv = self.setup_app_from_commandline(argv)
  File "/user/local/python3/lib/python3.6/site-packages/celery/bin/base.py", line 481, in setup_app_from_commandline
    self.app = self.find_app(app)
  File "/user/local/python3/lib/python3.6/site-packages/celery/bin/base.py", line 503, in find_app
    return find_app(app, symbol_by_name=self.symbol_by_name)
  File "/user/local/python3/lib/python3.6/site-packages/celery/app/utils.py", line 358, in find_app
    sym = imp(app)
  File "/user/local/python3/lib/python3.6/site-packages/celery/utils/imports.py", line 101, in import_from_cwd
    return imp(module, package=package)
  File "/user/local/python3/lib/python3.6/importlib/__init__.py", line 126, in import_module
    return _bootstrap._gcd_import(name[level:], package, level)
  File "<frozen importlib._bootstrap>", line 994, in _gcd_import
  File "<frozen importlib._bootstrap>", line 971, in _find_and_load
  File "<frozen importlib._bootstrap>", line 955, in _find_and_load_unlocked
  File "<frozen importlib._bootstrap>", line 665, in _load_unlocked
  File "<frozen importlib._bootstrap_external>", line 674, in exec_module
  File "<frozen importlib._bootstrap_external>", line 781, in get_code
  File "<frozen importlib._bootstrap_external>", line 741, in source_to_code
  File "<frozen importlib._bootstrap>", line 219, in _call_with_frames_removed
  File "/www/wwwroot/kaoweitong_spider/kaoweitongapp/tasks.py", line 130
    self.sr.del(key)
              ^
SyntaxError: invalid syntax
Traceback (most recent call last):
  File "/user/local/python3/lib/python3.6/site-packages/celery/app/utils.py", line 355, in find_app
    sym = symbol_by_name(app, imp=imp)
  File "/user/local/python3/lib/python3.6/site-packages/celery/bin/base.py", line 506, in symbol_by_name
    return imports.symbol_by_name(name, imp=imp)
  File "/user/local/python3/lib/python3.6/site-packages/kombu/utils/imports.py", line 61, in symbol_by_name
    return getattr(module, cls_name) if cls_name else module
AttributeError: module 'kaoweitongapp' has no attribute 'tasks'

During handling of the above exception, another exception occurred:

Traceback (most recent call last):
  File "/usr/bin/celery", line 11, in <module>
    sys.exit(main())
  File "/user/local/python3/lib/python3.6/site-packages/celery/__main__.py", line 14, in main
    _main()
  File "/user/local/python3/lib/python3.6/site-packages/celery/bin/celery.py", line 326, in main
    cmd.execute_from_commandline(argv)
  File "/user/local/python3/lib/python3.6/site-packages/celery/bin/celery.py", line 488, in execute_from_commandline
    super(CeleryCommand, self).execute_from_commandline(argv)))
  File "/user/local/python3/lib/python3.6/site-packages/celery/bin/base.py", line 279, in execute_from_commandline
    argv = self.setup_app_from_commandline(argv)
  File "/user/local/python3/lib/python3.6/site-packages/celery/bin/base.py", line 481, in setup_app_from_commandline
    self.app = self.find_app(app)
  File "/user/local/python3/lib/python3.6/site-packages/celery/bin/base.py", line 503, in find_app
    return find_app(app, symbol_by_name=self.symbol_by_name)
  File "/user/local/python3/lib/python3.6/site-packages/celery/app/utils.py", line 358, in find_app
    sym = imp(app)
  File "/user/local/python3/lib/python3.6/site-packages/celery/utils/imports.py", line 101, in import_from_cwd
    return imp(module, package=package)
  File "/user/local/python3/lib/python3.6/importlib/__init__.py", line 126, in import_module
    return _bootstrap._gcd_import(name[level:], package, level)
  File "<frozen importlib._bootstrap>", line 994, in _gcd_import
  File "<frozen importlib._bootstrap>", line 971, in _find_and_load
  File "<frozen importlib._bootstrap>", line 955, in _find_and_load_unlocked
  File "<frozen importlib._bootstrap>", line 665, in _load_unlocked
  File "<frozen importlib._bootstrap_external>", line 674, in exec_module
  File "<frozen importlib._bootstrap_external>", line 781, in get_code
  File "<frozen importlib._bootstrap_external>", line 741, in source_to_code
  File "<frozen importlib._bootstrap>", line 219, in _call_with_frames_removed
  File "/www/wwwroot/kaoweitong_spider/kaoweitongapp/tasks.py", line 130
    self.sr.del(key)
              ^
SyntaxError: invalid syntax
Traceback (most recent call last):
  File "/user/local/python3/lib/python3.6/site-packages/celery/app/utils.py", line 355, in find_app
    sym = symbol_by_name(app, imp=imp)
  File "/user/local/python3/lib/python3.6/site-packages/celery/bin/base.py", line 506, in symbol_by_name
    return imports.symbol_by_name(name, imp=imp)
  File "/user/local/python3/lib/python3.6/site-packages/kombu/utils/imports.py", line 61, in symbol_by_name
    return getattr(module, cls_name) if cls_name else module
AttributeError: module 'kaoweitongapp' has no attribute 'tasks'

During handling of the above exception, another exception occurred:

Traceback (most recent call last):
  File "/usr/bin/celery", line 11, in <module>
    sys.exit(main())
  File "/user/local/python3/lib/python3.6/site-packages/celery/__main__.py", line 14, in main
    _main()
  File "/user/local/python3/lib/python3.6/site-packages/celery/bin/celery.py", line 326, in main
    cmd.execute_from_commandline(argv)
  File "/user/local/python3/lib/python3.6/site-packages/celery/bin/celery.py", line 488, in execute_from_commandline
    super(CeleryCommand, self).execute_from_commandline(argv)))
  File "/user/local/python3/lib/python3.6/site-packages/celery/bin/base.py", line 279, in execute_from_commandline
    argv = self.setup_app_from_commandline(argv)
  File "/user/local/python3/lib/python3.6/site-packages/celery/bin/base.py", line 481, in setup_app_from_commandline
    self.app = self.find_app(app)
  File "/user/local/python3/lib/python3.6/site-packages/celery/bin/base.py", line 503, in find_app
    return find_app(app, symbol_by_name=self.symbol_by_name)
  File "/user/local/python3/lib/python3.6/site-packages/celery/app/utils.py", line 358, in find_app
    sym = imp(app)
  File "/user/local/python3/lib/python3.6/site-packages/celery/utils/imports.py", line 101, in import_from_cwd
    return imp(module, package=package)
  File "/user/local/python3/lib/python3.6/importlib/__init__.py", line 126, in import_module
    return _bootstrap._gcd_import(name[level:], package, level)
  File "<frozen importlib._bootstrap>", line 994, in _gcd_import
  File "<frozen importlib._bootstrap>", line 971, in _find_and_load
  File "<frozen importlib._bootstrap>", line 955, in _find_and_load_unlocked
  File "<frozen importlib._bootstrap>", line 665, in _load_unlocked
  File "<frozen importlib._bootstrap_external>", line 674, in exec_module
  File "<frozen importlib._bootstrap_external>", line 781, in get_code
  File "<frozen importlib._bootstrap_external>", line 741, in source_to_code
  File "<frozen importlib._bootstrap>", line 219, in _call_with_frames_removed
  File "/www/wwwroot/kaoweitong_spider/kaoweitongapp/tasks.py", line 130
    self.sr.del(key)
              ^
SyntaxError: invalid syntax
Traceback (most recent call last):
  File "/user/local/python3/lib/python3.6/site-packages/celery/app/utils.py", line 355, in find_app
    sym = symbol_by_name(app, imp=imp)
  File "/user/local/python3/lib/python3.6/site-packages/celery/bin/base.py", line 506, in symbol_by_name
    return imports.symbol_by_name(name, imp=imp)
  File "/user/local/python3/lib/python3.6/site-packages/kombu/utils/imports.py", line 61, in symbol_by_name
    return getattr(module, cls_name) if cls_name else module
AttributeError: module 'kaoweitongapp' has no attribute 'tasks'

During handling of the above exception, another exception occurred:

Traceback (most recent call last):
  File "/usr/bin/celery", line 11, in <module>
    sys.exit(main())
  File "/user/local/python3/lib/python3.6/site-packages/celery/__main__.py", line 14, in main
    _main()
  File "/user/local/python3/lib/python3.6/site-packages/celery/bin/celery.py", line 326, in main
    cmd.execute_from_commandline(argv)
  File "/user/local/python3/lib/python3.6/site-packages/celery/bin/celery.py", line 488, in execute_from_commandline
    super(CeleryCommand, self).execute_from_commandline(argv)))
  File "/user/local/python3/lib/python3.6/site-packages/celery/bin/base.py", line 279, in execute_from_commandline
    argv = self.setup_app_from_commandline(argv)
  File "/user/local/python3/lib/python3.6/site-packages/celery/bin/base.py", line 481, in setup_app_from_commandline
    self.app = self.find_app(app)
  File "/user/local/python3/lib/python3.6/site-packages/celery/bin/base.py", line 503, in find_app
    return find_app(app, symbol_by_name=self.symbol_by_name)
  File "/user/local/python3/lib/python3.6/site-packages/celery/app/utils.py", line 358, in find_app
    sym = imp(app)
  File "/user/local/python3/lib/python3.6/site-packages/celery/utils/imports.py", line 101, in import_from_cwd
    return imp(module, package=package)
  File "/user/local/python3/lib/python3.6/importlib/__init__.py", line 126, in import_module
    return _bootstrap._gcd_import(name[level:], package, level)
  File "<frozen importlib._bootstrap>", line 994, in _gcd_import
  File "<frozen importlib._bootstrap>", line 971, in _find_and_load
  File "<frozen importlib._bootstrap>", line 955, in _find_and_load_unlocked
  File "<frozen importlib._bootstrap>", line 665, in _load_unlocked
  File "<frozen importlib._bootstrap_external>", line 674, in exec_module
  File "<frozen importlib._bootstrap_external>", line 781, in get_code
  File "<frozen importlib._bootstrap_external>", line 741, in source_to_code
  File "<frozen importlib._bootstrap>", line 219, in _call_with_frames_removed
  File "/www/wwwroot/kaoweitong_spider/kaoweitongapp/tasks.py", line 130
    self.sr.del(key)
              ^
SyntaxError: invalid syntax
Traceback (most recent call last):
  File "/user/local/python3/lib/python3.6/site-packages/celery/app/utils.py", line 355, in find_app
    sym = symbol_by_name(app, imp=imp)
  File "/user/local/python3/lib/python3.6/site-packages/celery/bin/base.py", line 506, in symbol_by_name
    return imports.symbol_by_name(name, imp=imp)
  File "/user/local/python3/lib/python3.6/site-packages/kombu/utils/imports.py", line 61, in symbol_by_name
    return getattr(module, cls_name) if cls_name else module
AttributeError: module 'kaoweitongapp' has no attribute 'tasks'

During handling of the above exception, another exception occurred:

Traceback (most recent call last):
  File "/usr/bin/celery", line 11, in <module>
    sys.exit(main())
  File "/user/local/python3/lib/python3.6/site-packages/celery/__main__.py", line 14, in main
    _main()
  File "/user/local/python3/lib/python3.6/site-packages/celery/bin/celery.py", line 326, in main
    cmd.execute_from_commandline(argv)
  File "/user/local/python3/lib/python3.6/site-packages/celery/bin/celery.py", line 488, in execute_from_commandline
    super(CeleryCommand, self).execute_from_commandline(argv)))
  File "/user/local/python3/lib/python3.6/site-packages/celery/bin/base.py", line 279, in execute_from_commandline
    argv = self.setup_app_from_commandline(argv)
  File "/user/local/python3/lib/python3.6/site-packages/celery/bin/base.py", line 481, in setup_app_from_commandline
    self.app = self.find_app(app)
  File "/user/local/python3/lib/python3.6/site-packages/celery/bin/base.py", line 503, in find_app
    return find_app(app, symbol_by_name=self.symbol_by_name)
  File "/user/local/python3/lib/python3.6/site-packages/celery/app/utils.py", line 358, in find_app
    sym = imp(app)
  File "/user/local/python3/lib/python3.6/site-packages/celery/utils/imports.py", line 101, in import_from_cwd
    return imp(module, package=package)
  File "/user/local/python3/lib/python3.6/importlib/__init__.py", line 126, in import_module
    return _bootstrap._gcd_import(name[level:], package, level)
  File "<frozen importlib._bootstrap>", line 994, in _gcd_import
  File "<frozen importlib._bootstrap>", line 971, in _find_and_load
  File "<frozen importlib._bootstrap>", line 955, in _find_and_load_unlocked
  File "<frozen importlib._bootstrap>", line 665, in _load_unlocked
  File "<frozen importlib._bootstrap_external>", line 674, in exec_module
  File "<frozen importlib._bootstrap_external>", line 781, in get_code
  File "<frozen importlib._bootstrap_external>", line 741, in source_to_code
  File "<frozen importlib._bootstrap>", line 219, in _call_with_frames_removed
  File "/www/wwwroot/kaoweitong_spider/kaoweitongapp/tasks.py", line 130
    self.sr.del(key)
              ^
SyntaxError: invalid syntax
Traceback (most recent call last):
  File "/user/local/python3/lib/python3.6/site-packages/celery/app/utils.py", line 355, in find_app
    sym = symbol_by_name(app, imp=imp)
  File "/user/local/python3/lib/python3.6/site-packages/celery/bin/base.py", line 506, in symbol_by_name
    return imports.symbol_by_name(name, imp=imp)
  File "/user/local/python3/lib/python3.6/site-packages/kombu/utils/imports.py", line 61, in symbol_by_name
    return getattr(module, cls_name) if cls_name else module
AttributeError: module 'kaoweitongapp' has no attribute 'tasks'

During handling of the above exception, another exception occurred:

Traceback (most recent call last):
  File "/usr/bin/celery", line 11, in <module>
    sys.exit(main())
  File "/user/local/python3/lib/python3.6/site-packages/celery/__main__.py", line 14, in main
    _main()
  File "/user/local/python3/lib/python3.6/site-packages/celery/bin/celery.py", line 326, in main
    cmd.execute_from_commandline(argv)
  File "/user/local/python3/lib/python3.6/site-packages/celery/bin/celery.py", line 488, in execute_from_commandline
    super(CeleryCommand, self).execute_from_commandline(argv)))
  File "/user/local/python3/lib/python3.6/site-packages/celery/bin/base.py", line 279, in execute_from_commandline
    argv = self.setup_app_from_commandline(argv)
  File "/user/local/python3/lib/python3.6/site-packages/celery/bin/base.py", line 481, in setup_app_from_commandline
    self.app = self.find_app(app)
  File "/user/local/python3/lib/python3.6/site-packages/celery/bin/base.py", line 503, in find_app
    return find_app(app, symbol_by_name=self.symbol_by_name)
  File "/user/local/python3/lib/python3.6/site-packages/celery/app/utils.py", line 358, in find_app
    sym = imp(app)
  File "/user/local/python3/lib/python3.6/site-packages/celery/utils/imports.py", line 101, in import_from_cwd
    return imp(module, package=package)
  File "/user/local/python3/lib/python3.6/importlib/__init__.py", line 126, in import_module
    return _bootstrap._gcd_import(name[level:], package, level)
  File "<frozen importlib._bootstrap>", line 994, in _gcd_import
  File "<frozen importlib._bootstrap>", line 971, in _find_and_load
  File "<frozen importlib._bootstrap>", line 955, in _find_and_load_unlocked
  File "<frozen importlib._bootstrap>", line 665, in _load_unlocked
  File "<frozen importlib._bootstrap_external>", line 674, in exec_module
  File "<frozen importlib._bootstrap_external>", line 781, in get_code
  File "<frozen importlib._bootstrap_external>", line 741, in source_to_code
  File "<frozen importlib._bootstrap>", line 219, in _call_with_frames_removed
  File "/www/wwwroot/kaoweitong_spider/kaoweitongapp/tasks.py", line 130
    self.sr.del(key)
              ^
SyntaxError: invalid syntax
Traceback (most recent call last):
  File "/user/local/python3/lib/python3.6/site-packages/celery/app/utils.py", line 355, in find_app
    sym = symbol_by_name(app, imp=imp)
  File "/user/local/python3/lib/python3.6/site-packages/celery/bin/base.py", line 506, in symbol_by_name
    return imports.symbol_by_name(name, imp=imp)
  File "/user/local/python3/lib/python3.6/site-packages/kombu/utils/imports.py", line 61, in symbol_by_name
    return getattr(module, cls_name) if cls_name else module
AttributeError: module 'kaoweitongapp' has no attribute 'tasks'

During handling of the above exception, another exception occurred:

Traceback (most recent call last):
  File "/usr/bin/celery", line 11, in <module>
    sys.exit(main())
  File "/user/local/python3/lib/python3.6/site-packages/celery/__main__.py", line 14, in main
    _main()
  File "/user/local/python3/lib/python3.6/site-packages/celery/bin/celery.py", line 326, in main
    cmd.execute_from_commandline(argv)
  File "/user/local/python3/lib/python3.6/site-packages/celery/bin/celery.py", line 488, in execute_from_commandline
    super(CeleryCommand, self).execute_from_commandline(argv)))
  File "/user/local/python3/lib/python3.6/site-packages/celery/bin/base.py", line 279, in execute_from_commandline
    argv = self.setup_app_from_commandline(argv)
  File "/user/local/python3/lib/python3.6/site-packages/celery/bin/base.py", line 481, in setup_app_from_commandline
    self.app = self.find_app(app)
  File "/user/local/python3/lib/python3.6/site-packages/celery/bin/base.py", line 503, in find_app
    return find_app(app, symbol_by_name=self.symbol_by_name)
  File "/user/local/python3/lib/python3.6/site-packages/celery/app/utils.py", line 358, in find_app
    sym = imp(app)
  File "/user/local/python3/lib/python3.6/site-packages/celery/utils/imports.py", line 101, in import_from_cwd
    return imp(module, package=package)
  File "/user/local/python3/lib/python3.6/importlib/__init__.py", line 126, in import_module
    return _bootstrap._gcd_import(name[level:], package, level)
  File "<frozen importlib._bootstrap>", line 994, in _gcd_import
  File "<frozen importlib._bootstrap>", line 971, in _find_and_load
  File "<frozen importlib._bootstrap>", line 955, in _find_and_load_unlocked
  File "<frozen importlib._bootstrap>", line 665, in _load_unlocked
  File "<frozen importlib._bootstrap_external>", line 674, in exec_module
  File "<frozen importlib._bootstrap_external>", line 781, in get_code
  File "<frozen importlib._bootstrap_external>", line 741, in source_to_code
  File "<frozen importlib._bootstrap>", line 219, in _call_with_frames_removed
  File "/www/wwwroot/kaoweitong_spider/kaoweitongapp/tasks.py", line 130
    self.sr.del(key)
              ^
SyntaxError: invalid syntax
Traceback (most recent call last):
  File "/user/local/python3/lib/python3.6/site-packages/celery/app/utils.py", line 355, in find_app
    sym = symbol_by_name(app, imp=imp)
  File "/user/local/python3/lib/python3.6/site-packages/celery/bin/base.py", line 506, in symbol_by_name
    return imports.symbol_by_name(name, imp=imp)
  File "/user/local/python3/lib/python3.6/site-packages/kombu/utils/imports.py", line 61, in symbol_by_name
    return getattr(module, cls_name) if cls_name else module
AttributeError: module 'kaoweitongapp' has no attribute 'tasks'

During handling of the above exception, another exception occurred:

Traceback (most recent call last):
  File "/usr/bin/celery", line 11, in <module>
    sys.exit(main())
  File "/user/local/python3/lib/python3.6/site-packages/celery/__main__.py", line 14, in main
    _main()
  File "/user/local/python3/lib/python3.6/site-packages/celery/bin/celery.py", line 326, in main
    cmd.execute_from_commandline(argv)
  File "/user/local/python3/lib/python3.6/site-packages/celery/bin/celery.py", line 488, in execute_from_commandline
    super(CeleryCommand, self).execute_from_commandline(argv)))
  File "/user/local/python3/lib/python3.6/site-packages/celery/bin/base.py", line 279, in execute_from_commandline
    argv = self.setup_app_from_commandline(argv)
  File "/user/local/python3/lib/python3.6/site-packages/celery/bin/base.py", line 481, in setup_app_from_commandline
    self.app = self.find_app(app)
  File "/user/local/python3/lib/python3.6/site-packages/celery/bin/base.py", line 503, in find_app
    return find_app(app, symbol_by_name=self.symbol_by_name)
  File "/user/local/python3/lib/python3.6/site-packages/celery/app/utils.py", line 358, in find_app
    sym = imp(app)
  File "/user/local/python3/lib/python3.6/site-packages/celery/utils/imports.py", line 101, in import_from_cwd
    return imp(module, package=package)
  File "/user/local/python3/lib/python3.6/importlib/__init__.py", line 126, in import_module
    return _bootstrap._gcd_import(name[level:], package, level)
  File "<frozen importlib._bootstrap>", line 994, in _gcd_import
  File "<frozen importlib._bootstrap>", line 971, in _find_and_load
  File "<frozen importlib._bootstrap>", line 955, in _find_and_load_unlocked
  File "<frozen importlib._bootstrap>", line 665, in _load_unlocked
  File "<frozen importlib._bootstrap_external>", line 674, in exec_module
  File "<frozen importlib._bootstrap_external>", line 781, in get_code
  File "<frozen importlib._bootstrap_external>", line 741, in source_to_code
  File "<frozen importlib._bootstrap>", line 219, in _call_with_frames_removed
  File "/www/wwwroot/kaoweitong_spider/kaoweitongapp/tasks.py", line 130
    self.sr.del(key)
              ^
SyntaxError: invalid syntax
Traceback (most recent call last):
  File "/user/local/python3/lib/python3.6/site-packages/celery/app/utils.py", line 355, in find_app
    sym = symbol_by_name(app, imp=imp)
  File "/user/local/python3/lib/python3.6/site-packages/celery/bin/base.py", line 506, in symbol_by_name
    return imports.symbol_by_name(name, imp=imp)
  File "/user/local/python3/lib/python3.6/site-packages/kombu/utils/imports.py", line 61, in symbol_by_name
    return getattr(module, cls_name) if cls_name else module
AttributeError: module 'kaoweitongapp' has no attribute 'tasks'

During handling of the above exception, another exception occurred:

Traceback (most recent call last):
  File "/usr/bin/celery", line 11, in <module>
    sys.exit(main())
  File "/user/local/python3/lib/python3.6/site-packages/celery/__main__.py", line 14, in main
    _main()
  File "/user/local/python3/lib/python3.6/site-packages/celery/bin/celery.py", line 326, in main
    cmd.execute_from_commandline(argv)
  File "/user/local/python3/lib/python3.6/site-packages/celery/bin/celery.py", line 488, in execute_from_commandline
    super(CeleryCommand, self).execute_from_commandline(argv)))
  File "/user/local/python3/lib/python3.6/site-packages/celery/bin/base.py", line 279, in execute_from_commandline
    argv = self.setup_app_from_commandline(argv)
  File "/user/local/python3/lib/python3.6/site-packages/celery/bin/base.py", line 481, in setup_app_from_commandline
    self.app = self.find_app(app)
  File "/user/local/python3/lib/python3.6/site-packages/celery/bin/base.py", line 503, in find_app
    return find_app(app, symbol_by_name=self.symbol_by_name)
  File "/user/local/python3/lib/python3.6/site-packages/celery/app/utils.py", line 358, in find_app
    sym = imp(app)
  File "/user/local/python3/lib/python3.6/site-packages/celery/utils/imports.py", line 101, in import_from_cwd
    return imp(module, package=package)
  File "/user/local/python3/lib/python3.6/importlib/__init__.py", line 126, in import_module
    return _bootstrap._gcd_import(name[level:], package, level)
  File "<frozen importlib._bootstrap>", line 994, in _gcd_import
  File "<frozen importlib._bootstrap>", line 971, in _find_and_load
  File "<frozen importlib._bootstrap>", line 955, in _find_and_load_unlocked
  File "<frozen importlib._bootstrap>", line 665, in _load_unlocked
  File "<frozen importlib._bootstrap_external>", line 674, in exec_module
  File "<frozen importlib._bootstrap_external>", line 781, in get_code
  File "<frozen importlib._bootstrap_external>", line 741, in source_to_code
  File "<frozen importlib._bootstrap>", line 219, in _call_with_frames_removed
  File "/www/wwwroot/kaoweitong_spider/kaoweitongapp/tasks.py", line 130
    self.sr.del(key)
              ^
SyntaxError: invalid syntax
Traceback (most recent call last):
  File "/user/local/python3/lib/python3.6/site-packages/celery/app/utils.py", line 355, in find_app
    sym = symbol_by_name(app, imp=imp)
  File "/user/local/python3/lib/python3.6/site-packages/celery/bin/base.py", line 506, in symbol_by_name
    return imports.symbol_by_name(name, imp=imp)
  File "/user/local/python3/lib/python3.6/site-packages/kombu/utils/imports.py", line 61, in symbol_by_name
    return getattr(module, cls_name) if cls_name else module
AttributeError: module 'kaoweitongapp' has no attribute 'tasks'

During handling of the above exception, another exception occurred:

Traceback (most recent call last):
  File "/usr/bin/celery", line 11, in <module>
    sys.exit(main())
  File "/user/local/python3/lib/python3.6/site-packages/celery/__main__.py", line 14, in main
    _main()
  File "/user/local/python3/lib/python3.6/site-packages/celery/bin/celery.py", line 326, in main
    cmd.execute_from_commandline(argv)
  File "/user/local/python3/lib/python3.6/site-packages/celery/bin/celery.py", line 488, in execute_from_commandline
    super(CeleryCommand, self).execute_from_commandline(argv)))
  File "/user/local/python3/lib/python3.6/site-packages/celery/bin/base.py", line 279, in execute_from_commandline
    argv = self.setup_app_from_commandline(argv)
  File "/user/local/python3/lib/python3.6/site-packages/celery/bin/base.py", line 481, in setup_app_from_commandline
    self.app = self.find_app(app)
  File "/user/local/python3/lib/python3.6/site-packages/celery/bin/base.py", line 503, in find_app
    return find_app(app, symbol_by_name=self.symbol_by_name)
  File "/user/local/python3/lib/python3.6/site-packages/celery/app/utils.py", line 358, in find_app
    sym = imp(app)
  File "/user/local/python3/lib/python3.6/site-packages/celery/utils/imports.py", line 101, in import_from_cwd
    return imp(module, package=package)
  File "/user/local/python3/lib/python3.6/importlib/__init__.py", line 126, in import_module
    return _bootstrap._gcd_import(name[level:], package, level)
  File "<frozen importlib._bootstrap>", line 994, in _gcd_import
  File "<frozen importlib._bootstrap>", line 971, in _find_and_load
  File "<frozen importlib._bootstrap>", line 955, in _find_and_load_unlocked
  File "<frozen importlib._bootstrap>", line 665, in _load_unlocked
  File "<frozen importlib._bootstrap_external>", line 674, in exec_module
  File "<frozen importlib._bootstrap_external>", line 781, in get_code
  File "<frozen importlib._bootstrap_external>", line 741, in source_to_code
  File "<frozen importlib._bootstrap>", line 219, in _call_with_frames_removed
  File "/www/wwwroot/kaoweitong_spider/kaoweitongapp/tasks.py", line 130
    self.sr.del(key)
              ^
SyntaxError: invalid syntax
Traceback (most recent call last):
  File "/user/local/python3/lib/python3.6/site-packages/celery/app/utils.py", line 355, in find_app
    sym = symbol_by_name(app, imp=imp)
  File "/user/local/python3/lib/python3.6/site-packages/celery/bin/base.py", line 506, in symbol_by_name
    return imports.symbol_by_name(name, imp=imp)
  File "/user/local/python3/lib/python3.6/site-packages/kombu/utils/imports.py", line 61, in symbol_by_name
    return getattr(module, cls_name) if cls_name else module
AttributeError: module 'kaoweitongapp' has no attribute 'tasks'

During handling of the above exception, another exception occurred:

Traceback (most recent call last):
  File "/usr/bin/celery", line 11, in <module>
    sys.exit(main())
  File "/user/local/python3/lib/python3.6/site-packages/celery/__main__.py", line 14, in main
    _main()
  File "/user/local/python3/lib/python3.6/site-packages/celery/bin/celery.py", line 326, in main
    cmd.execute_from_commandline(argv)
  File "/user/local/python3/lib/python3.6/site-packages/celery/bin/celery.py", line 488, in execute_from_commandline
    super(CeleryCommand, self).execute_from_commandline(argv)))
  File "/user/local/python3/lib/python3.6/site-packages/celery/bin/base.py", line 279, in execute_from_commandline
    argv = self.setup_app_from_commandline(argv)
  File "/user/local/python3/lib/python3.6/site-packages/celery/bin/base.py", line 481, in setup_app_from_commandline
    self.app = self.find_app(app)
  File "/user/local/python3/lib/python3.6/site-packages/celery/bin/base.py", line 503, in find_app
    return find_app(app, symbol_by_name=self.symbol_by_name)
  File "/user/local/python3/lib/python3.6/site-packages/celery/app/utils.py", line 358, in find_app
    sym = imp(app)
  File "/user/local/python3/lib/python3.6/site-packages/celery/utils/imports.py", line 101, in import_from_cwd
    return imp(module, package=package)
  File "/user/local/python3/lib/python3.6/importlib/__init__.py", line 126, in import_module
    return _bootstrap._gcd_import(name[level:], package, level)
  File "<frozen importlib._bootstrap>", line 994, in _gcd_import
  File "<frozen importlib._bootstrap>", line 971, in _find_and_load
  File "<frozen importlib._bootstrap>", line 955, in _find_and_load_unlocked
  File "<frozen importlib._bootstrap>", line 665, in _load_unlocked
  File "<frozen importlib._bootstrap_external>", line 674, in exec_module
  File "<frozen importlib._bootstrap_external>", line 781, in get_code
  File "<frozen importlib._bootstrap_external>", line 741, in source_to_code
  File "<frozen importlib._bootstrap>", line 219, in _call_with_frames_removed
  File "/www/wwwroot/kaoweitong_spider/kaoweitongapp/tasks.py", line 130
    self.sr.del(key)
              ^
SyntaxError: invalid syntax
Traceback (most recent call last):
  File "/user/local/python3/lib/python3.6/site-packages/celery/app/utils.py", line 355, in find_app
    sym = symbol_by_name(app, imp=imp)
  File "/user/local/python3/lib/python3.6/site-packages/celery/bin/base.py", line 506, in symbol_by_name
    return imports.symbol_by_name(name, imp=imp)
  File "/user/local/python3/lib/python3.6/site-packages/kombu/utils/imports.py", line 61, in symbol_by_name
    return getattr(module, cls_name) if cls_name else module
AttributeError: module 'kaoweitongapp' has no attribute 'tasks'

During handling of the above exception, another exception occurred:

Traceback (most recent call last):
  File "/usr/bin/celery", line 11, in <module>
    sys.exit(main())
  File "/user/local/python3/lib/python3.6/site-packages/celery/__main__.py", line 14, in main
    _main()
  File "/user/local/python3/lib/python3.6/site-packages/celery/bin/celery.py", line 326, in main
    cmd.execute_from_commandline(argv)
  File "/user/local/python3/lib/python3.6/site-packages/celery/bin/celery.py", line 488, in execute_from_commandline
    super(CeleryCommand, self).execute_from_commandline(argv)))
  File "/user/local/python3/lib/python3.6/site-packages/celery/bin/base.py", line 279, in execute_from_commandline
    argv = self.setup_app_from_commandline(argv)
  File "/user/local/python3/lib/python3.6/site-packages/celery/bin/base.py", line 481, in setup_app_from_commandline
    self.app = self.find_app(app)
  File "/user/local/python3/lib/python3.6/site-packages/celery/bin/base.py", line 503, in find_app
    return find_app(app, symbol_by_name=self.symbol_by_name)
  File "/user/local/python3/lib/python3.6/site-packages/celery/app/utils.py", line 358, in find_app
    sym = imp(app)
  File "/user/local/python3/lib/python3.6/site-packages/celery/utils/imports.py", line 101, in import_from_cwd
    return imp(module, package=package)
  File "/user/local/python3/lib/python3.6/importlib/__init__.py", line 126, in import_module
    return _bootstrap._gcd_import(name[level:], package, level)
  File "<frozen importlib._bootstrap>", line 994, in _gcd_import
  File "<frozen importlib._bootstrap>", line 971, in _find_and_load
  File "<frozen importlib._bootstrap>", line 955, in _find_and_load_unlocked
  File "<frozen importlib._bootstrap>", line 665, in _load_unlocked
  File "<frozen importlib._bootstrap_external>", line 674, in exec_module
  File "<frozen importlib._bootstrap_external>", line 781, in get_code
  File "<frozen importlib._bootstrap_external>", line 741, in source_to_code
  File "<frozen importlib._bootstrap>", line 219, in _call_with_frames_removed
  File "/www/wwwroot/kaoweitong_spider/kaoweitongapp/tasks.py", line 130
    self.sr.del(key)
              ^
SyntaxError: invalid syntax
/user/local/python3/lib/python3.6/site-packages/celery/platforms.py:795: RuntimeWarning: You're running the worker with superuser privileges: this is
absolutely not recommended!

Please specify a different user using the -u option.

User information: uid=0 euid=0 gid=0 egid=0

  uid=uid, euid=euid, gid=gid, egid=egid,
[2018-05-03 18:03:03,466: INFO/MainProcess] Connected to redis://localhost:6379/0
[2018-05-03 18:03:03,473: INFO/MainProcess] mingle: searching for neighbors
[2018-05-03 18:03:04,488: INFO/MainProcess] mingle: all alone
[2018-05-03 18:03:04,495: INFO/MainProcess] celery@VM_0_13_centos ready.
[2018-05-03 18:03:13,568: INFO/MainProcess] Received task: kaoweitongapp.tasks.weixininfo[4df271bb-a501-43cc-a43b-a8e3486609b1]  
/user/local/python3/lib/python3.6/site-packages/celery/platforms.py:795: RuntimeWarning: You're running the worker with superuser privileges: this is
absolutely not recommended!

Please specify a different user using the -u option.

User information: uid=0 euid=0 gid=0 egid=0

  uid=uid, euid=euid, gid=gid, egid=egid,
[2018-05-03 18:03:18,576: WARNING/ForkPoolWorker-1] TD妞
[2018-05-03 18:03:18,576: WARNING/ForkPoolWorker-1] L-
[2018-05-03 18:03:18,576: WARNING/ForkPoolWorker-1] damo
[2018-05-03 18:03:18,576: WARNING/ForkPoolWorker-1] L-
[2018-05-03 18:03:18,576: WARNING/ForkPoolWorker-1] 备尘埃
[2018-05-03 18:03:18,576: WARNING/ForkPoolWorker-1] L-
[2018-05-03 18:03:18,576: WARNING/ForkPoolWorker-1] L-
[2018-05-03 18:03:18,576: WARNING/ForkPoolWorker-1] L-
[2018-05-03 18:03:18,576: WARNING/ForkPoolWorker-1] 渐行渐远渐无书
[2018-05-03 18:03:18,576: WARNING/ForkPoolWorker-1] L-
[2018-05-03 18:03:18,576: WARNING/ForkPoolWorker-1] TD课代表.
[2018-05-03 18:03:18,576: WARNING/ForkPoolWorker-1] L-
[2018-05-03 18:03:18,576: WARNING/ForkPoolWorker-1] L-
[2018-05-03 18:03:18,577: WARNING/ForkPoolWorker-1] L-
[2018-05-03 18:03:19,829: WARNING/ForkPoolWorker-1] 发送成功
[2018-05-03 18:03:19,866: INFO/ForkPoolWorker-1] Task kaoweitongapp.tasks.weixininfo[4df271bb-a501-43cc-a43b-a8e3486609b1] succeeded in 6.296954074990936s: None

worker: Warm shutdown (MainProcess)
 
 -------------- celery@VM_0_13_centos v4.1.0 (latentcall)
---- **** ----- 
--- * ***  * -- Linux-3.10.0-514.26.2.el7.x86_64-x86_64-with-centos-7.2.1511-Core 2018-05-03 18:03:03
-- * - **** --- 
- ** ---------- [config]
- ** ---------- .> app:         kaoweitongapp/tasks:0x7f0453da5eb8
- ** ---------- .> transport:   redis://localhost:6379/0
- ** ---------- .> results:     disabled://
- *** --- * --- .> concurrency: 2 (prefork)
-- ******* ---- .> task events: OFF (enable -E to monitor tasks in this worker)
--- ***** ----- 
 -------------- [queues]
                .> celery           exchange=celery(direct) key=celery
                

[tasks]
  . kaoweitongapp.tasks.check_neea
  . kaoweitongapp.tasks.weixininfo

/user/local/python3/lib/python3.6/site-packages/celery/platforms.py:795: RuntimeWarning: You're running the worker with superuser privileges: this is
absolutely not recommended!

Please specify a different user using the -u option.

User information: uid=0 euid=0 gid=0 egid=0

  uid=uid, euid=euid, gid=gid, egid=egid,
[2018-05-03 18:05:26,363: INFO/MainProcess] Connected to redis://localhost:6379/0
[2018-05-03 18:05:26,371: INFO/MainProcess] mingle: searching for neighbors
[2018-05-03 18:05:27,386: INFO/MainProcess] mingle: all alone
[2018-05-03 18:05:27,391: INFO/MainProcess] celery@VM_0_13_centos ready.
[2018-05-03 18:05:38,579: INFO/MainProcess] Received task: kaoweitongapp.tasks.weixininfo[3e7c5d28-01ae-43cc-bf0e-be2d5aafe7e9]  
/user/local/python3/lib/python3.6/site-packages/celery/platforms.py:795: RuntimeWarning: You're running the worker with superuser privileges: this is
absolutely not recommended!

Please specify a different user using the -u option.

User information: uid=0 euid=0 gid=0 egid=0

  uid=uid, euid=euid, gid=gid, egid=egid,
[2018-05-03 18:05:43,587: WARNING/ForkPoolWorker-1] damo
[2018-05-03 18:05:43,587: WARNING/ForkPoolWorker-1] L-
[2018-05-03 18:05:43,587: WARNING/ForkPoolWorker-1] TD妞
[2018-05-03 18:05:43,587: WARNING/ForkPoolWorker-1] L-
[2018-05-03 18:05:43,588: WARNING/ForkPoolWorker-1] 渐行渐远渐无书
[2018-05-03 18:05:43,588: WARNING/ForkPoolWorker-1] L-
[2018-05-03 18:05:43,588: WARNING/ForkPoolWorker-1] L-
[2018-05-03 18:05:43,588: WARNING/ForkPoolWorker-1] L-
[2018-05-03 18:05:43,588: WARNING/ForkPoolWorker-1] TD课代表.
[2018-05-03 18:05:43,588: WARNING/ForkPoolWorker-1] L-
[2018-05-03 18:05:43,588: WARNING/ForkPoolWorker-1] L-
[2018-05-03 18:05:43,588: WARNING/ForkPoolWorker-1] L-
[2018-05-03 18:05:43,588: WARNING/ForkPoolWorker-1] 备尘埃
[2018-05-03 18:05:43,588: WARNING/ForkPoolWorker-1] L-
[2018-05-03 18:05:46,213: WARNING/ForkPoolWorker-1] 发送成功
[2018-05-03 18:05:46,253: INFO/ForkPoolWorker-1] Task kaoweitongapp.tasks.weixininfo[3e7c5d28-01ae-43cc-bf0e-be2d5aafe7e9] succeeded in 7.672738008084707s: None
[2018-05-03 18:08:20,814: INFO/MainProcess] Received task: kaoweitongapp.tasks.weixininfo[24dea748-9687-4786-a7ff-ba8b46fb9fdf]  
[2018-05-03 18:08:25,821: WARNING/ForkPoolWorker-1] damo
[2018-05-03 18:08:25,821: WARNING/ForkPoolWorker-1] None
[2018-05-03 18:08:25,821: WARNING/ForkPoolWorker-1] TD妞
[2018-05-03 18:08:25,821: WARNING/ForkPoolWorker-1] None
[2018-05-03 18:08:25,821: WARNING/ForkPoolWorker-1] 渐行渐远渐无书
[2018-05-03 18:08:25,821: WARNING/ForkPoolWorker-1] None
[2018-05-03 18:08:25,821: WARNING/ForkPoolWorker-1] L-
[2018-05-03 18:08:25,821: WARNING/ForkPoolWorker-1] None
[2018-05-03 18:08:25,821: WARNING/ForkPoolWorker-1] TD课代表.
[2018-05-03 18:08:25,821: WARNING/ForkPoolWorker-1] None
[2018-05-03 18:08:25,821: WARNING/ForkPoolWorker-1] L-
[2018-05-03 18:08:25,821: WARNING/ForkPoolWorker-1] None
[2018-05-03 18:08:25,822: WARNING/ForkPoolWorker-1] 备尘埃
[2018-05-03 18:08:25,822: WARNING/ForkPoolWorker-1] None
[2018-05-03 18:08:26,696: WARNING/ForkPoolWorker-1] 发送成功
[2018-05-03 18:08:26,733: INFO/ForkPoolWorker-1] Task kaoweitongapp.tasks.weixininfo[24dea748-9687-4786-a7ff-ba8b46fb9fdf] succeeded in 5.917817919049412s: None

worker: Warm shutdown (MainProcess)
 
 -------------- celery@VM_0_13_centos v4.1.0 (latentcall)
---- **** ----- 
--- * ***  * -- Linux-3.10.0-514.26.2.el7.x86_64-x86_64-with-centos-7.2.1511-Core 2018-05-03 18:05:26
-- * - **** --- 
- ** ---------- [config]
- ** ---------- .> app:         kaoweitongapp/tasks:0x7fbaa1ef5f28
- ** ---------- .> transport:   redis://localhost:6379/0
- ** ---------- .> results:     disabled://
- *** --- * --- .> concurrency: 2 (prefork)
-- ******* ---- .> task events: OFF (enable -E to monitor tasks in this worker)
--- ***** ----- 
 -------------- [queues]
                .> celery           exchange=celery(direct) key=celery
                

[tasks]
  . kaoweitongapp.tasks.check_neea
  . kaoweitongapp.tasks.weixininfo

/user/local/python3/lib/python3.6/site-packages/celery/platforms.py:795: RuntimeWarning: You're running the worker with superuser privileges: this is
absolutely not recommended!

Please specify a different user using the -u option.

User information: uid=0 euid=0 gid=0 egid=0

  uid=uid, euid=euid, gid=gid, egid=egid,
[2018-05-03 18:16:04,930: INFO/MainProcess] Connected to redis://localhost:6379/0
[2018-05-03 18:16:04,937: INFO/MainProcess] mingle: searching for neighbors
[2018-05-03 18:16:05,952: INFO/MainProcess] mingle: all alone
[2018-05-03 18:16:05,959: INFO/MainProcess] celery@VM_0_13_centos ready.
[2018-05-03 18:16:17,540: INFO/MainProcess] Received task: kaoweitongapp.tasks.weixininfo[c902713b-833c-44c3-8386-b7086ecce402]  
/user/local/python3/lib/python3.6/site-packages/celery/platforms.py:795: RuntimeWarning: You're running the worker with superuser privileges: this is
absolutely not recommended!

Please specify a different user using the -u option.

User information: uid=0 euid=0 gid=0 egid=0

  uid=uid, euid=euid, gid=gid, egid=egid,
[2018-05-03 18:16:22,548: WARNING/ForkPoolWorker-1] TD课代表.
[2018-05-03 18:16:22,548: WARNING/ForkPoolWorker-1] L-
[2018-05-03 18:16:22,549: WARNING/ForkPoolWorker-1] damo
[2018-05-03 18:16:22,549: WARNING/ForkPoolWorker-1] L-
[2018-05-03 18:16:22,549: WARNING/ForkPoolWorker-1] L-
[2018-05-03 18:16:22,549: WARNING/ForkPoolWorker-1] L-
[2018-05-03 18:16:22,549: WARNING/ForkPoolWorker-1] TD妞
[2018-05-03 18:16:22,549: WARNING/ForkPoolWorker-1] L-
[2018-05-03 18:16:22,549: WARNING/ForkPoolWorker-1] 渐行渐远渐无书
[2018-05-03 18:16:22,549: WARNING/ForkPoolWorker-1] L-
[2018-05-03 18:16:22,549: WARNING/ForkPoolWorker-1] 备尘埃
[2018-05-03 18:16:22,549: WARNING/ForkPoolWorker-1] L-
[2018-05-03 18:16:22,549: WARNING/ForkPoolWorker-1] L-
[2018-05-03 18:16:22,549: WARNING/ForkPoolWorker-1] L-
[2018-05-03 18:16:22,564: ERROR/ForkPoolWorker-1] Task kaoweitongapp.tasks.weixininfo[c902713b-833c-44c3-8386-b7086ecce402] raised unexpected: AttributeError("'dict' object has no attribute 'encode'",)
Traceback (most recent call last):
  File "/user/local/python3/lib/python3.6/site-packages/celery/app/trace.py", line 374, in trace_task
    R = retval = fun(*args, **kwargs)
  File "/user/local/python3/lib/python3.6/site-packages/celery/app/trace.py", line 629, in __protected_call__
    return self.run(*args, **kwargs)
  File "/www/wwwroot/kaoweitong_spider/kaoweitongapp/tasks.py", line 210, in weixininfo
    send_mail(temp_dict)
  File "/www/wwwroot/kaoweitong_spider/kaoweitongapp/tasks.py", line 172, in send_mail
    msg = MIMEText(content)
  File "/user/local/python3/lib/python3.6/email/mime/text.py", line 34, in __init__
    _text.encode('us-ascii')
AttributeError: 'dict' object has no attribute 'encode'

worker: Warm shutdown (MainProcess)
 
 -------------- celery@VM_0_13_centos v4.1.0 (latentcall)
---- **** ----- 
--- * ***  * -- Linux-3.10.0-514.26.2.el7.x86_64-x86_64-with-centos-7.2.1511-Core 2018-05-03 18:16:04
-- * - **** --- 
- ** ---------- [config]
- ** ---------- .> app:         kaoweitongapp/tasks:0x7fd6e8e3ff28
- ** ---------- .> transport:   redis://localhost:6379/0
- ** ---------- .> results:     disabled://
- *** --- * --- .> concurrency: 2 (prefork)
-- ******* ---- .> task events: OFF (enable -E to monitor tasks in this worker)
--- ***** ----- 
 -------------- [queues]
                .> celery           exchange=celery(direct) key=celery
                

[tasks]
  . kaoweitongapp.tasks.check_neea
  . kaoweitongapp.tasks.weixininfo

/user/local/python3/lib/python3.6/site-packages/celery/platforms.py:795: RuntimeWarning: You're running the worker with superuser privileges: this is
absolutely not recommended!

Please specify a different user using the -u option.

User information: uid=0 euid=0 gid=0 egid=0

  uid=uid, euid=euid, gid=gid, egid=egid,
[2018-05-03 18:18:10,406: INFO/MainProcess] Connected to redis://localhost:6379/0
[2018-05-03 18:18:10,414: INFO/MainProcess] mingle: searching for neighbors
[2018-05-03 18:18:11,429: INFO/MainProcess] mingle: all alone
[2018-05-03 18:18:11,435: INFO/MainProcess] celery@VM_0_13_centos ready.

worker: Warm shutdown (MainProcess)
 
 -------------- celery@VM_0_13_centos v4.1.0 (latentcall)
---- **** ----- 
--- * ***  * -- Linux-3.10.0-514.26.2.el7.x86_64-x86_64-with-centos-7.2.1511-Core 2018-05-03 18:18:10
-- * - **** --- 
- ** ---------- [config]
- ** ---------- .> app:         kaoweitongapp/tasks:0x7f5d39212f28
- ** ---------- .> transport:   redis://localhost:6379/0
- ** ---------- .> results:     disabled://
- *** --- * --- .> concurrency: 2 (prefork)
-- ******* ---- .> task events: OFF (enable -E to monitor tasks in this worker)
--- ***** ----- 
 -------------- [queues]
                .> celery           exchange=celery(direct) key=celery
                

[tasks]
  . kaoweitongapp.tasks.check_neea
  . kaoweitongapp.tasks.weixininfo

/user/local/python3/lib/python3.6/site-packages/celery/platforms.py:795: RuntimeWarning: You're running the worker with superuser privileges: this is
absolutely not recommended!

Please specify a different user using the -u option.

User information: uid=0 euid=0 gid=0 egid=0

  uid=uid, euid=euid, gid=gid, egid=egid,
[2018-05-03 18:18:15,264: INFO/MainProcess] Connected to redis://localhost:6379/0
[2018-05-03 18:18:15,272: INFO/MainProcess] mingle: searching for neighbors
[2018-05-03 18:18:16,287: INFO/MainProcess] mingle: all alone
[2018-05-03 18:18:16,293: INFO/MainProcess] celery@VM_0_13_centos ready.

worker: Warm shutdown (MainProcess)
 
 -------------- celery@VM_0_13_centos v4.1.0 (latentcall)
---- **** ----- 
--- * ***  * -- Linux-3.10.0-514.26.2.el7.x86_64-x86_64-with-centos-7.2.1511-Core 2018-05-03 18:18:15
-- * - **** --- 
- ** ---------- [config]
- ** ---------- .> app:         kaoweitongapp/tasks:0x7f50ca0c9b00
- ** ---------- .> transport:   redis://localhost:6379/0
- ** ---------- .> results:     disabled://
- *** --- * --- .> concurrency: 2 (prefork)
-- ******* ---- .> task events: OFF (enable -E to monitor tasks in this worker)
--- ***** ----- 
 -------------- [queues]
                .> celery           exchange=celery(direct) key=celery
                

[tasks]
  . kaoweitongapp.tasks.check_neea
  . kaoweitongapp.tasks.weixininfo

/user/local/python3/lib/python3.6/site-packages/celery/platforms.py:795: RuntimeWarning: You're running the worker with superuser privileges: this is
absolutely not recommended!

Please specify a different user using the -u option.

User information: uid=0 euid=0 gid=0 egid=0

  uid=uid, euid=euid, gid=gid, egid=egid,
[2018-05-03 18:19:19,947: INFO/MainProcess] Connected to redis://localhost:6379/0
[2018-05-03 18:19:19,955: INFO/MainProcess] mingle: searching for neighbors
[2018-05-03 18:19:20,970: INFO/MainProcess] mingle: all alone
[2018-05-03 18:19:20,976: INFO/MainProcess] celery@VM_0_13_centos ready.

worker: Warm shutdown (MainProcess)
 
 -------------- celery@VM_0_13_centos v4.1.0 (latentcall)
---- **** ----- 
--- * ***  * -- Linux-3.10.0-514.26.2.el7.x86_64-x86_64-with-centos-7.2.1511-Core 2018-05-03 18:19:19
-- * - **** --- 
- ** ---------- [config]
- ** ---------- .> app:         kaoweitongapp/tasks:0x7fdcfa32ab00
- ** ---------- .> transport:   redis://localhost:6379/0
- ** ---------- .> results:     disabled://
- *** --- * --- .> concurrency: 2 (prefork)
-- ******* ---- .> task events: OFF (enable -E to monitor tasks in this worker)
--- ***** ----- 
 -------------- [queues]
                .> celery           exchange=celery(direct) key=celery
                

[tasks]
  . kaoweitongapp.tasks.check_neea
  . kaoweitongapp.tasks.weixininfo

/user/local/python3/lib/python3.6/site-packages/celery/platforms.py:795: RuntimeWarning: You're running the worker with superuser privileges: this is
absolutely not recommended!

Please specify a different user using the -u option.

User information: uid=0 euid=0 gid=0 egid=0

  uid=uid, euid=euid, gid=gid, egid=egid,
[2018-05-03 18:19:27,961: INFO/MainProcess] Connected to redis://localhost:6379/0
[2018-05-03 18:19:27,969: INFO/MainProcess] mingle: searching for neighbors
[2018-05-03 18:19:28,984: INFO/MainProcess] mingle: all alone
[2018-05-03 18:19:28,990: INFO/MainProcess] celery@VM_0_13_centos ready.
/user/local/python3/lib/python3.6/site-packages/celery/platforms.py:795: RuntimeWarning: You're running the worker with superuser privileges: this is
absolutely not recommended!

Please specify a different user using the -u option.

User information: uid=0 euid=0 gid=0 egid=0

  uid=uid, euid=euid, gid=gid, egid=egid,
[2018-05-03 18:19:39,466: INFO/MainProcess] Connected to redis://localhost:6379/0
[2018-05-03 18:19:39,472: INFO/MainProcess] mingle: searching for neighbors
[2018-05-03 18:19:40,487: INFO/MainProcess] mingle: all alone
[2018-05-03 18:19:40,494: INFO/MainProcess] celery@VM_0_13_centos ready.

worker: Warm shutdown (MainProcess)
 
 -------------- celery@VM_0_13_centos v4.1.0 (latentcall)
---- **** ----- 
--- * ***  * -- Linux-3.10.0-514.26.2.el7.x86_64-x86_64-with-centos-7.2.1511-Core 2018-05-03 18:19:39
-- * - **** --- 
- ** ---------- [config]
- ** ---------- .> app:         kaoweitongapp/tasks:0x7fc5e3b33b38
- ** ---------- .> transport:   redis://localhost:6379/0
- ** ---------- .> results:     disabled://
- *** --- * --- .> concurrency: 2 (prefork)
-- ******* ---- .> task events: OFF (enable -E to monitor tasks in this worker)
--- ***** ----- 
 -------------- [queues]
                .> celery           exchange=celery(direct) key=celery
                

[tasks]
  . kaoweitongapp.tasks.check_neea
  . kaoweitongapp.tasks.weixininfo

/user/local/python3/lib/python3.6/site-packages/celery/platforms.py:795: RuntimeWarning: You're running the worker with superuser privileges: this is
absolutely not recommended!

Please specify a different user using the -u option.

User information: uid=0 euid=0 gid=0 egid=0

  uid=uid, euid=euid, gid=gid, egid=egid,
[2018-05-03 18:19:58,850: INFO/MainProcess] Connected to redis://localhost:6379/0
[2018-05-03 18:19:58,856: INFO/MainProcess] mingle: searching for neighbors
[2018-05-03 18:19:59,871: INFO/MainProcess] mingle: all alone
[2018-05-03 18:19:59,878: INFO/MainProcess] celery@VM_0_13_centos ready.

worker: Warm shutdown (MainProcess)
 
 -------------- celery@VM_0_13_centos v4.1.0 (latentcall)
---- **** ----- 
--- * ***  * -- Linux-3.10.0-514.26.2.el7.x86_64-x86_64-with-centos-7.2.1511-Core 2018-05-03 18:19:58
-- * - **** --- 
- ** ---------- [config]
- ** ---------- .> app:         kaoweitongapp/tasks:0x7f5bf88e2b00
- ** ---------- .> transport:   redis://localhost:6379/0
- ** ---------- .> results:     disabled://
- *** --- * --- .> concurrency: 2 (prefork)
-- ******* ---- .> task events: OFF (enable -E to monitor tasks in this worker)
--- ***** ----- 
 -------------- [queues]
                .> celery           exchange=celery(direct) key=celery
                

[tasks]
  . kaoweitongapp.tasks.check_neea
  . kaoweitongapp.tasks.weixininfo

/user/local/python3/lib/python3.6/site-packages/celery/platforms.py:795: RuntimeWarning: You're running the worker with superuser privileges: this is
absolutely not recommended!

Please specify a different user using the -u option.

User information: uid=0 euid=0 gid=0 egid=0

  uid=uid, euid=euid, gid=gid, egid=egid,
[2018-05-03 18:21:10,048: INFO/MainProcess] Connected to redis://localhost:6379/0
[2018-05-03 18:21:10,055: INFO/MainProcess] mingle: searching for neighbors
[2018-05-03 18:21:11,070: INFO/MainProcess] mingle: all alone
[2018-05-03 18:21:11,077: INFO/MainProcess] celery@VM_0_13_centos ready.

worker: Warm shutdown (MainProcess)
 
 -------------- celery@VM_0_13_centos v4.1.0 (latentcall)
---- **** ----- 
--- * ***  * -- Linux-3.10.0-514.26.2.el7.x86_64-x86_64-with-centos-7.2.1511-Core 2018-05-03 18:21:10
-- * - **** --- 
- ** ---------- [config]
- ** ---------- .> app:         kaoweitongapp/tasks:0x7fc118c6fb00
- ** ---------- .> transport:   redis://localhost:6379/0
- ** ---------- .> results:     disabled://
- *** --- * --- .> concurrency: 2 (prefork)
-- ******* ---- .> task events: OFF (enable -E to monitor tasks in this worker)
--- ***** ----- 
 -------------- [queues]
                .> celery           exchange=celery(direct) key=celery
                

[tasks]
  . kaoweitongapp.tasks.check_neea
  . kaoweitongapp.tasks.weixininfo

/user/local/python3/lib/python3.6/site-packages/celery/platforms.py:795: RuntimeWarning: You're running the worker with superuser privileges: this is
absolutely not recommended!

Please specify a different user using the -u option.

User information: uid=0 euid=0 gid=0 egid=0

  uid=uid, euid=euid, gid=gid, egid=egid,
[2018-05-03 18:24:19,210: INFO/MainProcess] Connected to redis://localhost:6379/0
[2018-05-03 18:24:19,216: INFO/MainProcess] mingle: searching for neighbors
[2018-05-03 18:24:20,232: INFO/MainProcess] mingle: all alone
[2018-05-03 18:24:20,238: INFO/MainProcess] celery@VM_0_13_centos ready.
[2018-05-03 18:24:38,812: INFO/MainProcess] Received task: kaoweitongapp.tasks.weixininfo[686359f5-e928-4654-9c11-c546ac10201d]  
/user/local/python3/lib/python3.6/site-packages/celery/platforms.py:795: RuntimeWarning: You're running the worker with superuser privileges: this is
absolutely not recommended!

Please specify a different user using the -u option.

User information: uid=0 euid=0 gid=0 egid=0

  uid=uid, euid=euid, gid=gid, egid=egid,
[2018-05-03 18:24:43,820: WARNING/ForkPoolWorker-1] L-
[2018-05-03 18:24:43,820: WARNING/ForkPoolWorker-1] L-
[2018-05-03 18:24:43,820: WARNING/ForkPoolWorker-1] TD妞
[2018-05-03 18:24:43,820: WARNING/ForkPoolWorker-1] L-
[2018-05-03 18:24:43,820: WARNING/ForkPoolWorker-1] damo
[2018-05-03 18:24:43,820: WARNING/ForkPoolWorker-1] L-
[2018-05-03 18:24:43,820: WARNING/ForkPoolWorker-1] L-
[2018-05-03 18:24:43,820: WARNING/ForkPoolWorker-1] L-
[2018-05-03 18:24:43,820: WARNING/ForkPoolWorker-1] 渐行渐远渐无书
[2018-05-03 18:24:43,820: WARNING/ForkPoolWorker-1] L-
[2018-05-03 18:24:43,820: WARNING/ForkPoolWorker-1] TD课代表.
[2018-05-03 18:24:43,820: WARNING/ForkPoolWorker-1] L-
[2018-05-03 18:24:43,820: WARNING/ForkPoolWorker-1] 备尘埃
[2018-05-03 18:24:43,821: WARNING/ForkPoolWorker-1] L-
[2018-05-03 18:24:45,423: WARNING/ForkPoolWorker-1] 发送成功
[2018-05-03 18:24:45,468: INFO/ForkPoolWorker-1] Task kaoweitongapp.tasks.weixininfo[686359f5-e928-4654-9c11-c546ac10201d] succeeded in 6.655003271996975s: None

worker: Warm shutdown (MainProcess)
 
 -------------- celery@VM_0_13_centos v4.1.0 (latentcall)
---- **** ----- 
--- * ***  * -- Linux-3.10.0-514.26.2.el7.x86_64-x86_64-with-centos-7.2.1511-Core 2018-05-03 18:24:19
-- * - **** --- 
- ** ---------- [config]
- ** ---------- .> app:         kaoweitongapp/tasks:0x7f1c42391b38
- ** ---------- .> transport:   redis://localhost:6379/0
- ** ---------- .> results:     disabled://
- *** --- * --- .> concurrency: 2 (prefork)
-- ******* ---- .> task events: OFF (enable -E to monitor tasks in this worker)
--- ***** ----- 
 -------------- [queues]
                .> celery           exchange=celery(direct) key=celery
                

[tasks]
  . kaoweitongapp.tasks.check_neea
  . kaoweitongapp.tasks.weixininfo

/user/local/python3/lib/python3.6/site-packages/celery/platforms.py:795: RuntimeWarning: You're running the worker with superuser privileges: this is
absolutely not recommended!

Please specify a different user using the -u option.

User information: uid=0 euid=0 gid=0 egid=0

  uid=uid, euid=euid, gid=gid, egid=egid,
[2018-05-03 18:29:21,235: INFO/MainProcess] Connected to redis://localhost:6379/0
[2018-05-03 18:29:21,242: INFO/MainProcess] mingle: searching for neighbors
[2018-05-03 18:29:22,257: INFO/MainProcess] mingle: all alone
[2018-05-03 18:29:22,264: INFO/MainProcess] celery@VM_0_13_centos ready.

worker: Warm shutdown (MainProcess)
 
 -------------- celery@VM_0_13_centos v4.1.0 (latentcall)
---- **** ----- 
--- * ***  * -- Linux-3.10.0-514.26.2.el7.x86_64-x86_64-with-centos-7.2.1511-Core 2018-05-03 18:29:21
-- * - **** --- 
- ** ---------- [config]
- ** ---------- .> app:         kaoweitongapp/tasks:0x7f6e1a98cf28
- ** ---------- .> transport:   redis://localhost:6379/0
- ** ---------- .> results:     disabled://
- *** --- * --- .> concurrency: 2 (prefork)
-- ******* ---- .> task events: OFF (enable -E to monitor tasks in this worker)
--- ***** ----- 
 -------------- [queues]
                .> celery           exchange=celery(direct) key=celery
                

[tasks]
  . kaoweitongapp.tasks.check_neea
  . kaoweitongapp.tasks.weixininfo

/user/local/python3/lib/python3.6/site-packages/celery/platforms.py:795: RuntimeWarning: You're running the worker with superuser privileges: this is
absolutely not recommended!

Please specify a different user using the -u option.

User information: uid=0 euid=0 gid=0 egid=0

  uid=uid, euid=euid, gid=gid, egid=egid,
[2018-05-03 18:29:38,789: INFO/MainProcess] Connected to redis://localhost:6379/0
[2018-05-03 18:29:38,797: INFO/MainProcess] mingle: searching for neighbors
[2018-05-03 18:29:39,812: INFO/MainProcess] mingle: all alone
[2018-05-03 18:29:39,817: INFO/MainProcess] celery@VM_0_13_centos ready.

worker: Warm shutdown (MainProcess)
 
 -------------- celery@VM_0_13_centos v4.1.0 (latentcall)
---- **** ----- 
--- * ***  * -- Linux-3.10.0-514.26.2.el7.x86_64-x86_64-with-centos-7.2.1511-Core 2018-05-03 18:29:38
-- * - **** --- 
- ** ---------- [config]
- ** ---------- .> app:         kaoweitongapp/tasks:0x7fd15fb8ab38
- ** ---------- .> transport:   redis://localhost:6379/0
- ** ---------- .> results:     disabled://
- *** --- * --- .> concurrency: 2 (prefork)
-- ******* ---- .> task events: OFF (enable -E to monitor tasks in this worker)
--- ***** ----- 
 -------------- [queues]
                .> celery           exchange=celery(direct) key=celery
                

[tasks]
  . kaoweitongapp.tasks.check_neea
  . kaoweitongapp.tasks.weixininfo

/user/local/python3/lib/python3.6/site-packages/celery/platforms.py:795: RuntimeWarning: You're running the worker with superuser privileges: this is
absolutely not recommended!

Please specify a different user using the -u option.

User information: uid=0 euid=0 gid=0 egid=0

  uid=uid, euid=euid, gid=gid, egid=egid,
[2018-05-03 18:30:09,028: INFO/MainProcess] Connected to redis://localhost:6379/0
[2018-05-03 18:30:09,035: INFO/MainProcess] mingle: searching for neighbors
[2018-05-03 18:30:10,050: INFO/MainProcess] mingle: all alone
[2018-05-03 18:30:10,057: INFO/MainProcess] celery@VM_0_13_centos ready.
[2018-05-03 18:30:34,352: INFO/MainProcess] Received task: kaoweitongapp.tasks.weixininfo[93afa0ec-09d2-4744-b896-88330077f471]  
/user/local/python3/lib/python3.6/site-packages/celery/platforms.py:795: RuntimeWarning: You're running the worker with superuser privileges: this is
absolutely not recommended!

Please specify a different user using the -u option.

User information: uid=0 euid=0 gid=0 egid=0

  uid=uid, euid=euid, gid=gid, egid=egid,
[2018-05-03 18:30:39,360: WARNING/ForkPoolWorker-1] TD课代表.
[2018-05-03 18:30:39,360: WARNING/ForkPoolWorker-1] L-
[2018-05-03 18:30:39,360: WARNING/ForkPoolWorker-1] L-
[2018-05-03 18:30:39,360: WARNING/ForkPoolWorker-1] L-
[2018-05-03 18:30:39,360: WARNING/ForkPoolWorker-1] 渐行渐远渐无书
[2018-05-03 18:30:39,360: WARNING/ForkPoolWorker-1] L-
[2018-05-03 18:30:39,360: WARNING/ForkPoolWorker-1] L-
[2018-05-03 18:30:39,360: WARNING/ForkPoolWorker-1] L-
[2018-05-03 18:30:39,360: WARNING/ForkPoolWorker-1] 备尘埃
[2018-05-03 18:30:39,360: WARNING/ForkPoolWorker-1] L-
[2018-05-03 18:30:39,360: WARNING/ForkPoolWorker-1] TD妞
[2018-05-03 18:30:39,361: WARNING/ForkPoolWorker-1] L-
[2018-05-03 18:30:39,361: WARNING/ForkPoolWorker-1] damo
[2018-05-03 18:30:39,361: WARNING/ForkPoolWorker-1] L-
[2018-05-03 18:30:40,294: WARNING/ForkPoolWorker-1] 发送成功
[2018-05-03 18:30:40,330: INFO/ForkPoolWorker-1] Task kaoweitongapp.tasks.weixininfo[93afa0ec-09d2-4744-b896-88330077f471] succeeded in 5.976442700019106s: None
